Workbook
Name _Hlk186092945: Instructions!$A$1
Name All_amend: Dropdowns_Manual!$AN$2:$AN$84
Name All_crops: Dropdowns_Manual!$Q$2:$Q$162
Name All_equip: Dropdowns_Manual!$AI$2:$AI$200
Name AmendType: Dropdowns_Manual!$AJ$2:$AJ$19
Name AnimalDiv_GrazIntensity: Dropdowns_Manual!$AQ$2:$AQ$16
Name AnimalType: Dropdowns_Manual!$AP$2:$AP$65
Name Brassica: Dropdowns_Manual!$H$2:$H$51
Name Broadleaf_cool: Dropdowns_Manual!$J$2:$J$51
Name Broadleaf_warm: Dropdowns_Manual!$I$2:$I$51
Name crop_mix: Dropdowns_Manual!$E$2:$E$8
Name CropCategory: Dropdowns_Manual!$G$3:$G$19
Name CropDiv_YieldUnits: Dropdowns_Manual!$S$2:$S$26
Name CropIrrUnits: Dropdowns_Manual!$W$2:$W$15
Name CropResMgt: Dropdowns_Manual!$U$2:$U$37
Name CropType: Dropdowns_Manual!$F$2:$F$21
Name Cultivator: Dropdowns_Manual!$Z$2:$Z$200
Name Disk: Dropdowns_Manual!$AA$2:$AA$200
Name Fertilizer: Dropdowns_Manual!$AK$2:$AK$79
Name Grass_cool: Dropdowns_Manual!$L$2:$L$52
Name Grass_warm: Dropdowns_Manual!$K$2:$K$51
Name Harrow: Dropdowns_Manual!$AB$2:$AB$200
Name Horticulture: Dropdowns_Manual!$O$2:$O$53
Name Implement: Dropdowns_Manual!$AI$2:$AI$99
Name IrrType: Dropdowns_Manual!$V$2:$V$32
Name Legume_cool: Dropdowns_Manual!$N$2:$N$51
Name Legume_warm: Dropdowns_Manual!$M$2:$M$51
Name Lime: Dropdowns_Manual!$AL$2:$AL$24
Name Mgt_tile_years: Dropdowns_Manual!$D$2:$D$7
Name Mgt_TileDrain: Dropdowns_Manual!$C$2:$C$12
Name MgtUnit: Dropdowns_Formulas!$B$2:$B$200
Name MgtUnit_Study: Dropdowns_Manual!$B$2:$B$200
Name Miscellaneous: Dropdowns_Manual!$AH$2:$AH$200
Name OpsMgt: Dropdowns_Manual!$X$2:$X$25
Name Organic: Dropdowns_Manual!$AM$2:$AM$76
Name Other: Dropdowns_Manual!$R$2:$R$64
Name Pasture_Mixed: Dropdowns_Manual!$R$3:$R$200
Name Plow: Dropdowns_Manual!$AC$2:$AC$200
Name Roller_or_Packer: Dropdowns_Manual!$AD$2:$AD$100
Name Rotary_Equipment: Dropdowns_Manual!$AE$2:$AE$100
Name Saline: Dropdowns_Manual!$P$2:$P$50
Name Seedbed_Prep: Dropdowns_Manual!$AF$2:$AF$100
Name Soil_Conditioner: Dropdowns_Manual!$AG$2:$AG$100
Name SoilDist_OpsEquipCat: Dropdowns_Manual!$Y$2:$Y$16
Name States: Dropdowns_Manual!$A$2:$A$51
Name TermMethod: Dropdowns_Manual!$T$2:$T$54
Name User_Perm: Dropdowns_Manual!#REF!
Name Users: Dropdowns_Formulas!$A$2:$A$200

Sheet Instructions
A1: Notes and Instructions
A3: Note: Yellow highlight indicates columns that are required for SHMI calculations.
A4: All data should be entered based on the sample date for the Soil Carbon Collection Study
A6: Instructions – User_Info tab
A7: Please enter the best conact info for the farm of reference
A9: Instructions – Mgt_Unit tab
A10: The Mgt_Unit tab has been partially pre-populated from the shml_main.xlsx file. Farm name, field name, and tile drainage status need your input.
A12: Instructions – Crop_Diversity tab
A13: The Crop_Diversity tab is partially pre-populated from the shml_main.xlsx file.
A14: Starting with the MLSH sample date the first crop entry for each treatment should be the current crop at sampling (if sampling was during the growing season) or the previous crop (if sampling was done post-harvest). From there work backwards until an entire crop rotation is entered. For continuous cropping systems, please enter two crop years.
A15: 1. MGT_combo is a concatenation of project, farm name, field name, and treatment. Pre-entered values will not match the new concatenation after updating the Mgt_Unit tab. Please update all values in each MGT_combo column by selecting the appropriate new values in the dropdown menu.
A16: 2. Validate pre-entered crop rotation data is accurate.
... A32: 2. The current version of SHMI only includes presence/absence of animals. Please contact us if you’re interested in expanding the capability and integration of Animal Diversity into SHMI.

Sheet User_Info
A1: Description | B1: First Name | C1: Last Name | D1: Email | E1: Phone Number | F1: Interviewer name | G1: Interview Date | H1: User may add any notes here
A2: Type | B2: <character> | C2: <character> | D2: <character> | E2: <character> | F2: <character> | G2: <character> | H2: <character>
A3: Units | B3: NA | C3: NA | D3: NA | E3: NA | F3: NA | G3: MM/DD/YYYY | H3: NA
B4: user_first | C4: user_last | D4: user_email | E4: user_phone | F4: interviewer | G4: interview_date | H4: notes
B5: Zach | C5: McKee | D5: zmckeez@gmail.com | E5: 503-949-3116 | F5: Christy Tanner | G5: 46108 | H5: user is contact person for farm

Sheet Mgt_Unit
A1: Description | B1: Name of User | C1: Excel Unique ID | D1: Study | E1: Farm/Owner | F1: Field Name | G1: Latitude | H1: Longitude | I1: State | J1: County | K1: Field Polygon | L1: Name of field or treatment ID | M1: Tile Drainage | N1: Number of years under tile drainage | O1: User may add any notes here
A2: Type | B2: <dropdown> | C2: <auto-generated> | D2: <dropdown> | E2: <character> | F2: <character> | G2: <numeric> | H2: <numeric> | I2: <dropdown> | J2: <character> | K2: <geojson> | L2: <character> | M2: <dropdown> | N2: <dropdown> | O2: <character>
A3: Units | B3: NA | C3: NA | D3: NA | E3: NA | F3: NA | G3: dec degrees | H3: dec degrees | I3: NA | J3: NA | K3: NA | L3: NA | M3: NA | N3: NA | O3: NA
B4: user_name | C4: MGT_combo | D4: MGT_study | E4: MGT_farm | F4: MGT_field | G4: MGT_lat | H4: MGT_lon | I4: MGT_state | J4: MGT_county | K4: MGT_polygon | L4: MGT_trt | M4: MGT_tile_drain | N4: MGT_tile_years | O4: MGT_notes
B5: zach.mckee | C5: =IF(ISBLANK(D5), "", CONCATENATE(D5,"_",E5,"_",F5,"_",L5)) -> Tile_N_McKee_MANZI NW CORNER 15AC_Old | D5: Tile_N | E5: McKee | F5: MANZI NW CORNER 15AC | G5: 44.79301 | H5: -123.31054 | I5: Oregon | J5: Polk | L5: Old | M5: Yes
B6: zach.mckee | C6: =IF(ISBLANK(D6), "", CONCATENATE(D6,"_",E6,"_",F6,"_",L6)) -> Tile_N_McKee_MANZI PIVOT 115AC_Old | D6: Tile_N | E6: McKee | F6: MANZI PIVOT 115AC | G6: 44.79246 | H6: -123.30809 | I6: Oregon | J6: Polk | L6: Old | M6: Yes
B7: zach.mckee | C7: =IF(ISBLANK(D7), "", CONCATENATE(D7,"_",E7,"_",F7,"_",L7)) -> Tile_N_McKee_MRF DRIVE EAST 72AC_Old | D7: Tile_N | E7: McKee | F7: MRF DRIVE EAST 72AC | G7: 44.79417 | H7: -123.26835 | I7: Oregon | J7: Polk | L7: Old | M7: Yes
B8: zach.mckee | C8: =IF(ISBLANK(D8), "", CONCATENATE(D8,"_",E8,"_",F8,"_",L8)) -> Tile_N_McKee_MRF DRIVE WEST 60AC_Old | D8: Tile_N | E8: McKee | F8: MRF DRIVE WEST 60AC | G8: 44.79489 | H8: -123.26968 | I8: Oregon | J8: Polk | L8: Old | M8: Yes
B9: zach.mckee | C9: =IF(ISBLANK(D9), "", CONCATENATE(D9,"_",E9,"_",F9,"_",L9)) -> Tile_N_McKee_NOLAS 67AC_New | D9: Tile_N | E9: McKee | F9: NOLAS 67AC | G9: 44.80825 | H9: -123.31007 | I9: Oregon | J9: Polk | L9: New | M9: Yes
B10: zach.mckee | C10: =IF(ISBLANK(D10), "", CONCATENATE(D10,"_",E10,"_",F10,"_",L10)) -> Tile_N_McKee_OSBORNE FRONT WEST 40 AC_Untiled | D10: Tile_N | E10: McKee | F10: OSBORNE FRONT WEST 40 AC | G10: 44.79181 | H10: -123.32575 | I10: Oregon | J10: Polk | L10: Untiled | M10: No
B11: zach.mckee | C11: =IF(ISBLANK(D11), "", CONCATENATE(D11,"_",E11,"_",F11,"_",L11)) -> Tile_N_McKee_ZORA ANN N OF RD 45AC_Untiled | D11: Tile_N | E11: McKee | F11: ZORA ANN N OF RD 45AC | G11: 44.79163 | H11: -123.33122 | I11: Oregon | J11: Polk | L11: Untiled | M11: No
B12: zach.mckee | C12: =IF(ISBLANK(D12), "", CONCATENATE(D12,"_",E12,"_",F12,"_",L12)) -> Tile_N_McKee_ZORA ANN N OF RD BTM 60AC_Untiled | D12: Tile_N | E12: McKee | F12: ZORA ANN N OF RD BTM 60AC | G12: 44.79673 | H12: -123.33139 | I12: Oregon | J12: Polk | L12: Untiled | M12: No
B13: zach.mckee | C13: =IF(ISBLANK(D13), "", CONCATENATE(D13,"_",E13,"_",F13,"_",L13)) -> Tile_N_McKee_ZORA ANN S OF RD BTM 65AC_Untiled | D13: Tile_N | E13: McKee | F13: ZORA ANN S OF RD BTM 65AC | G13: 44.7869 | H13: -123.33071 | I13: Oregon | J13: Polk | L13: Untiled | M13: No
B14: zach.mckee | C14: =IF(ISBLANK(D14), "", CONCATENATE(D14,"_",E14,"_",F14,"_",L14)) -> Tile_N_McKee_ZORA ANN S OF RD 53AC_New | D14: Tile_N | E14: McKee | F14: ZORA ANN S OF RD 53AC | G14: 44.79082 | H14: -123.33104 | I14: Oregon | J14: Polk | L14: New | M14: Yes
C15: =IF(ISBLANK(D15), "", CONCATENATE(D15,"_",E15,"_",F15,"_",L15))
C16: =IF(ISBLANK(D16), "", CONCATENATE(D16,"_",E16,"_",F16,"_",L16))
C17: =IF(ISBLANK(D17), "", CONCATENATE(D17,"_",E17,"_",F17,"_",L17))
C18: =IF(ISBLANK(D18), "", CONCATENATE(D18,"_",E18,"_",F18,"_",L18))
C19: =IF(ISBLANK(D19), "", CONCATENATE(D19,"_",E19,"_",F19,"_",L19))
C20: =IF(ISBLANK(D20), "", CONCATENATE(D20,"_",E20,"_",F20,"_",L20))
C21: =IF(ISBLANK(D21), "", CONCATENATE(D21,"_",E21,"_",F21,"_",L21))
C22: =IF(ISBLANK(D22), "", CONCATENATE(D22,"_",E22,"_",F22,"_",L22))
C23: =IF(ISBLANK(D23), "", CONCATENATE(D23,"_",E23,"_",F23,"_",L23))
C24: =IF(ISBLANK(D24), "", CONCATENATE(D24,"_",E24,"_",F24,"_",L24))
C25: =IF(ISBLANK(D25), "", CONCATENATE(D25,"_",E25,"_",F25,"_",L25))
C26: =IF(ISBLANK(D26), "", CONCATENATE(D26,"_",E26,"_",F26,"_",L26))
... C102: =IF(ISBLANK(D102), "", CONCATENATE(D102,"_",E102,"_",F102,"_",L102))

Sheet Crop_Diversity
A1: Description | B1: Unique Mgt ID | C1: Crop Sequence Number | D1: Crop Mixture | E1: Crop category | F1: Crop Functional Group | G1: Crop Name | H1: Crop Planting Date | I1: Typical Harvest Month/Day | J1: Crop Termination Date | K1: Residue Management | L1: Average Yield (5-years) | M1: Crop Yield Units | N1: Irrigation category | O1: Total Annual irrigation | P1: User may add any notes here
A2: Type | B2: <dropdown> | C2: <integer> | D2: <dropdown> | E2: <dropdown> | F2: <dropdown> | G2: <dropdown> | H2: <date> | I2: <date> | J2: <date> | K2: <dropdown> | L2: <numeric> | M2: <dropdown> | N2: <dropdown> | O2: <integer> | P2: <character>
A3: Units | B3: NA | C3: NA | D3: NA | E3: NA | F3: NA | G3: NA | H3: MM/DD/YYYY | I3: MM/DD/YYYY | J3: MM/DD/YYYY | K3: NA | L3: <user-defined> | M3: NA | N3: NA | O3: inches
B4: MGT_combo | C4: CD_seq_num | D4: CD_mix | E4: CD_cat | F4: CD_group | G4: CD_name | H4: CD_plant_date | I4: CD_harv_date | J4: CD_term_date | K4: CD_res_mgt | L4: CD_yield | M4: CD_yield_units | N4: CD_irr_cat | O4: CD_irr_amt | P4: CD_notes
B5: Tile_N_McKee_MANZI NW CORNER 15AC_Old | C5: 1 | D5: No | E5: Perennial | F5: Grass_cool | G5: Fescue, Tall | H5: 43221 | J5: 46285 | K5: NA | L5: 1500 | M5: lbs/acre | N5: Sprinkler, Linear | O5: 1.5 | P5: 2018 irrigated at establishment only. no harvest for the first year of spring planted TF
B6: Tile_N_McKee_MANZI NW CORNER 15AC_Old | C6: 1 | D6: No | E6: Perennial | F6: Grass_cool | G6: Fescue, Tall | H6: 43221 | I6: 43651 | J6: 46285 | K6: baled | L6: 1500 | M6: lbs/acre | N6: None | O6: 0 | P6: 2019
B7: Tile_N_McKee_MANZI NW CORNER 15AC_Old | C7: 1 | D7: No | E7: Perennial | F7: Grass_cool | G7: Fescue, Tall | H7: 43221 | I7: 44017 | J7: 46285 | K7: baled | L7: 1500 | M7: lbs/acre | N7: None | O7: 0 | P7: 2020
B8: Tile_N_McKee_MANZI NW CORNER 15AC_Old | C8: 1 | D8: No | E8: Perennial | F8: Grass_cool | G8: Fescue, Tall | H8: 43221 | I8: 44382 | J8: 46285 | K8: baled | L8: 1500 | M8: lbs/acre | N8: None | O8: 0 | P8: 2021
B9: Tile_N_McKee_MANZI NW CORNER 15AC_Old | C9: 1 | D9: No | E9: Perennial | F9: Grass_cool | G9: Fescue, Tall | H9: 43221 | I9: 44747 | J9: 46285 | K9: baled | L9: 1500 | M9: lbs/acre | N9: None | O9: 0 | P9: 2022
B10: Tile_N_McKee_MANZI NW CORNER 15AC_Old | C10: 1 | D10: No | E10: Perennial | F10: Grass_cool | G10: Fescue, Tall | H10: 43221 | I10: 45112 | J10: 46285 | K10: baled | L10: 1500 | M10: lbs/acre | N10: None | O10: 0 | P10: 2023
B11: Tile_N_McKee_MANZI NW CORNER 15AC_Old | C11: 1 | D11: No | E11: Perennial | F11: Grass_cool | G11: Fescue, Tall | H11: 43221 | I11: 45478 | J11: 46285 | K11: baled | L11: 1500 | M11: lbs/acre | N11: None | O11: 0 | P11: 2024
B12: Tile_N_McKee_MANZI NW CORNER 15AC_Old | C12: 1 | D12: No | E12: Perennial | F12: Grass_cool | G12: Fescue, Tall | H12: 43221 | I12: 45843 | J12: 46285 | K12: baled | L12: 1500 | M12: lbs/acre | N12: None | O12: 0 | P12: 2025
B13: Tile_N_McKee_MANZI NW CORNER 15AC_Old | C13: 1 | D13: No | E13: Perennial | F13: Grass_cool | G13: Fescue, Tall | H13: 43221 | I13: 46208 | J13: 46285 | K13: baled | L13: 1500 | M13: lbs/acre | N13: None | O13: 0 | P13: 2026
B14: Tile_N_McKee_MANZI PIVOT 115AC_Old | C14: 1 | D14: Yes | E14: Perennial | F14: Broadleaf_cool | G14: Radish | H14: 43191 | I14: 43353 | J14: 43353 | K14: chop & flail | N14: None | O14: 0 | P14: 2018
B15: Tile_N_McKee_MANZI PIVOT 115AC_Old | C15: 1 | D15: Yes | E15: Perennial | F15: Legume_cool | G15: Clover, Red | H15: 43191 | I15: 43702 | J15: 44612 | K15: stubble | P15: 2019
B16: Tile_N_McKee_MANZI PIVOT 115AC_Old | C16: 1 | D16: Yes | E16: Perennial | F16: Legume_cool | G16: Clover, Red | H16: 43191 | I16: 44068 | J16: 44612 | K16: stubble | N16: Sprinkler, Pivot | O16: 1.5 | P16: 2020
B17: Tile_N_McKee_MANZI PIVOT 115AC_Old | C17: 1 | D17: Yes | E17: Perennial | F17: Legume_cool | G17: Clover, Red | H17: 43191 | I17: 44433 | J17: 44612 | K17: incorporated | N17: Sprinkler, Pivot | O17: 1.5 | P17: 2021
B18: Tile_N_McKee_MANZI PIVOT 115AC_Old | C18: 2 | D18: No | E18: Perennial | F18: Grass_cool | G18: Fescue, Tall | H18: 44682 | J18: 46285 | K18: NA | N18: Sprinkler, Pivot | O18: 5 | P18: 2022 no harvest for the first year of spring planted TF
B19: Tile_N_McKee_MANZI PIVOT 115AC_Old | C19: 2 | D19: No | E19: Perennial | F19: Grass_cool | G19: Fescue, Tall | H19: 44682 | I19: 45112 | J19: 46285 | K19: baled | L19: 1500 | M19: lbs/acre | N19: Sprinkler, Pivot | O19: 5 | P19: 2023
B20: Tile_N_McKee_MANZI PIVOT 115AC_Old | C20: 2 | D20: No | E20: Perennial | F20: Grass_cool | G20: Fescue, Tall | H20: 44682 | I20: 45478 | J20: 46285 | K20: baled | L20: 1500 | M20: lbs/acre | N20: Sprinkler, Pivot | O20: 5 | P20: 2024
B21: Tile_N_McKee_MANZI PIVOT 115AC_Old | C21: 2 | D21: No | E21: Perennial | F21: Grass_cool | G21: Fescue, Tall | H21: 44682 | I21: 45843 | J21: 46285 | K21: baled | L21: 1500 | M21: lbs/acre | N21: Sprinkler, Pivot | O21: 5 | P21: 2025
B22: Tile_N_McKee_MANZI PIVOT 115AC_Old | C22: 2 | D22: No | E22: Perennial | F22: Grass_cool | G22: Fescue, Tall | H22: 44682 | I22: 46208 | J22: 46285 | K22: baled | L22: 1500 | M22: lbs/acre | N22: Sprinkler, Pivot | O22: 5 | P22: 2026
B23: Tile_N_McKee_MRF DRIVE EAST 72AC_Old | C23: 1 | D23: No | E23: Perennial | F23: Grass_cool | G23: Ryegrass, Perennial | H23: 41937 | I23: 42566 | J23: 42786 | K23: baled | L23: 1700 | M23: lbs/acre | P23: 2016 Planting year is a guess
B24: Tile_N_McKee_MRF DRIVE EAST 72AC_Old | C24: 2 | D24: Yes | E24: Perennial | F24: Broadleaf_cool | G24: Radish | H24: 42826 | I24: 42988 | J24: 42988 | K24: stubble | P24: 2017
B25: Tile_N_McKee_MRF DRIVE EAST 72AC_Old | C25: 2 | D25: No | E25: Perennial | F25: Legume_cool | G25: Clover, Red | H25: 42826 | I25: 43337 | J25: 43728 | K25: stubble | P25: 2018
B26: Tile_N_McKee_MRF DRIVE EAST 72AC_Old | C26: 2 | D26: No | E26: Perennial | F26: Legume_cool | G26: Clover, Red | H26: 42826 | I26: 43702 | J26: 43728 | K26: stubble | P26: 2019
B27: Tile_N_McKee_MRF DRIVE EAST 72AC_Old | C27: 3 | D27: No | E27: Perennial | F27: Grass_cool | G27: Ryegrass, Perennial | H27: 43758 | I27: 44027 | J27: 44459 | K27: baled | L27: 1700 | M27: lbs/acre | P27: 2020
B28: Tile_N_McKee_MRF DRIVE EAST 72AC_Old | C28: 3 | D28: No | E28: Perennial | F28: Grass_cool | G28: Ryegrass, Perennial | H28: 43758 | I28: 44392 | J28: 44459 | K28: baled | L28: 1700 | M28: lbs/acre | P28: 2021
B29: Tile_N_McKee_MRF DRIVE EAST 72AC_Old | C29: 4 | D29: No | E29: Perennial | F29: Grass_cool | G29: Ryegrass, Perennial | H29: 44489 | I29: 44757 | J29: 45555 | K29: baled | L29: 1700 | M29: lbs/acre | P29: 2022
B30: Tile_N_McKee_MRF DRIVE EAST 72AC_Old | C30: 4 | D30: No | E30: Perennial | F30: Grass_cool | G30: Ryegrass, Perennial | H30: 44489 | I30: 45122 | J30: 45555 | K30: baled | L30: 1700 | M30: lbs/acre | P30: 2023
B31: Tile_N_McKee_MRF DRIVE EAST 72AC_Old | C31: 4 | D31: No | E31: Perennial | F31: Grass_cool | G31: Ryegrass, Perennial | H31: 44489 | I31: 45488 | J31: 45555 | K31: baled | L31: 1700 | M31: lbs/acre | P31: 2024
B32: Tile_N_McKee_MRF DRIVE EAST 72AC_Old | C32: 5 | D32: No | E32: Annual | F32: Grass_cool | G32: Wheat, Winter | H32: 45580 | I32: 45853 | J32: 45853 | P32: 2025
B33: Tile_N_McKee_MRF DRIVE WEST 60AC_Old | C33: 1 | D33: No | E33: Perennial | F33: Legume_cool | G33: Clover, Red | H33: 41730 | I33: 42607 | J33: 42633 | P33: 2016
B34: Tile_N_McKee_MRF DRIVE WEST 60AC_Old | C34: 2 | D34: No | E34: Perennial | F34: Grass_cool | G34: Ryegrass, Perennial | H34: 42663 | I34: 42931 | J34: 43881 | K34: baled | L34: 1700 | M34: lbs/acre | P34: 2017
B35: Tile_N_McKee_MRF DRIVE WEST 60AC_Old | C35: 2 | D35: No | E35: Perennial | F35: Grass_cool | G35: Ryegrass, Perennial | H35: 42663 | I35: 43296 | J35: 43881 | K35: baled | L35: 1700 | M35: lbs/acre | P35: 2018
B36: Tile_N_McKee_MRF DRIVE WEST 60AC_Old | C36: 2 | D36: No | E36: Perennial | F36: Grass_cool | G36: Ryegrass, Perennial | H36: 42663 | I36: 43661 | J36: 43881 | K36: baled | L36: 1700 | M36: lbs/acre | P36: 2019
B37: Tile_N_McKee_MRF DRIVE WEST 60AC_Old | C37: 3 | D37: No | E37: Annual | F37: Broadleaf_cool | G37: Radish | H37: 43922 | I37: 44084 | J37: 44084 | P37: 2020
B38: Tile_N_McKee_MRF DRIVE WEST 60AC_Old | C38: 4 | D38: No | E38: Perennial | F38: Grass_cool | G38: Ryegrass, Perennial | H38: 44124 | I38: 44392 | J38: 45189 | K38: baled | L38: 1700 | M38: lbs/acre | P38: 2021
B39: Tile_N_McKee_MRF DRIVE WEST 60AC_Old | C39: 4 | D39: No | E39: Perennial | F39: Grass_cool | G39: Ryegrass, Perennial | H39: 44124 | I39: 44757 | J39: 45189 | K39: baled | L39: 1700 | M39: lbs/acre | P39: 2022
B40: Tile_N_McKee_MRF DRIVE WEST 60AC_Old | C40: 4 | D40: No | E40: Perennial | F40: Grass_cool | G40: Ryegrass, Perennial | H40: 44124 | I40: 45122 | J40: 45189 | K40: baled | L40: 1700 | M40: lbs/acre | P40: 2023
...

Sheet Soil_Disturbance
A1: Description | B1: Unique Mgt ID | C1: Plant phase operation was performed during | D1: Date operation was performed | E1: Operation Goal (free form) | F1: Common name for piece of equipment | G1: Equipment category | H1: Equipment name | I1: Proportion of soil affected | J1: Depth of soil affected | K1: User may add any notes here
A2: Type | B2: <dropdown> | C2: <dropdown> | D2: <date> | E2: <character> | F2: <character> | G2: <dropdown> | H2: <dropdown> | I2: <autofill> | J2: <integer> | K2: <character>
A3: Units | B3: NA | C3: NA | D3: MM/DD/YYYY | E3: NA | F3: NA | G3: NA | H3: NA | I3: proportion | J3: inches | K3: NA
B4: MGT_combo | C4: SD_phase | D4: SD_date | E4: SD_goal | F4: SD_name | G4: SD_equip_cat | H4: SD_equip | I4: SD_mixeff | J4: SD_depth | K4: SD_notes
B5: Tile_N_McKee_MANZI NW CORNER 15AC_Old | C5: Pre-Plant | D5: 43215 | E5: Work Ground | F5: Disk | G5: Disk | H5: Single Disk | I5: =IF(ISBLANK(H5), "", VLOOKUP(H5,Dropdowns_Formulas!C$2:D$100,2,FALSE)) -> 0.45 | J5: 6 | K5: Terlinate by working in the spring with a disk (6" deep) (only) 1x, maybe 2x, Note: Get Depth from Grower
B6: Tile_N_McKee_MANZI NW CORNER 15AC_Old | C6: Pre-Plant | D6: 43215 | E6: Work Ground | F6: Harrow | G6: Harrow | H6: Harrow (Tines) | I6: =IF(ISBLANK(H6), "", VLOOKUP(H6,Dropdowns_Formulas!C$2:D$100,2,FALSE)) -> 0.2 | J6: 3 | K6: harrow (2-3" deep) 2-3x
B7: Tile_N_McKee_MANZI PIVOT 115AC_Old | C7: Pre-Plant | D7: 43174 | E7: Work Ground | F7: Disk | G7: Disk | H7: Single Disk | I7: =IF(ISBLANK(H7), "", VLOOKUP(H7,Dropdowns_Formulas!C$2:D$100,2,FALSE)) -> 0.45 | J7: 6 | K7: RAD and RC up until 2022 (TF was underseed into RC in spring) RC harvested, irrigated
B8: Tile_N_McKee_MANZI PIVOT 115AC_Old | C8: Pre-Plant | D8: 43175 | E8: Work Ground | F8: Harrow | G8: Harrow | H8: Harrow (Tines) | I8: =IF(ISBLANK(H8), "", VLOOKUP(H8,Dropdowns_Formulas!C$2:D$100,2,FALSE)) -> 0.2 | J8: 3 | K8: disk 1 -2 x then harrow
B9: Tile_N_McKee_MRF DRIVE EAST 72AC_Old | C9: Termination | D9: 42799 | E9: Termination | F9: Disk Ripper | G9: Disk | H9: Disk Chisel (Mulch Tiller) | I9: =IF(ISBLANK(H9), "", VLOOKUP(H9,Dropdowns_Formulas!C$2:D$100,2,FALSE)) -> 0.55 | J9: 15
B10: Tile_N_McKee_MRF DRIVE EAST 72AC_Old | C10: Termination | D10: 42799 | E10: Termination | F10: Harrow | G10: Harrow | H10: Harrow (Tines) | I10: =IF(ISBLANK(H10), "", VLOOKUP(H10,Dropdowns_Formulas!C$2:D$100,2,FALSE)) -> 0.2 | J10: 3 | K10: disked 2x (after radish or clover) harrowed, let sprout, spray, then carbon plant
B11: Tile_N_McKee_MRF DRIVE EAST 72AC_Old | C11: Pre-Plant | D11: 43733 | E11: Work ground/Termination of Clover | F11: Disk | G11: Disk | H11: Single Disk | I11: =IF(ISBLANK(H11), "", VLOOKUP(H11,Dropdowns_Formulas!C$2:D$100,2,FALSE)) -> 0.45 | J11: 6
B12: Tile_N_McKee_MRF DRIVE EAST 72AC_Old | C12: Pre-Plant | D12: 43733 | E12: Work ground/Termination of Clover | F12: Harrow | G12: Harrow | H12: Harrow (Tines) | I12: =IF(ISBLANK(H12), "", VLOOKUP(H12,Dropdowns_Formulas!C$2:D$100,2,FALSE)) -> 0.2 | J12: 3 | K12: Terminated and replanted in PRG, unsure of termination timeline
B13: Tile_N_McKee_MRF DRIVE EAST 72AC_Old | C13: Termination | D13: 44829 | E13: Termination | F13: Disk Ripper | G13: Disk | H13: Disk Chisel (Mulch Tiller) | I13: =IF(ISBLANK(H13), "", VLOOKUP(H13,Dropdowns_Formulas!C$2:D$100,2,FALSE)) -> 0.55 | J13: 15
B14: Tile_N_McKee_MRF DRIVE EAST 72AC_Old | C14: Termination | D14: 44829 | E14: Termination | F14: Harrow | G14: Harrow | H14: Harrow (Tines) | I14: =IF(ISBLANK(H14), "", VLOOKUP(H14,Dropdowns_Formulas!C$2:D$100,2,FALSE)) -> 0.2 | J14: 3
B15: Tile_N_McKee_MRF DRIVE EAST 72AC_Old | C15: Pre-Plant | D15: 44835 | E15: Work ground/Termination of Clover | F15: Disk | G15: Disk | H15: Single Disk | I15: =IF(ISBLANK(H15), "", VLOOKUP(H15,Dropdowns_Formulas!C$2:D$100,2,FALSE)) -> 0.45 | J15: 6
B16: Tile_N_McKee_MRF DRIVE EAST 72AC_Old | C16: Pre-Plant | D16: 44835 | E16: Work ground/Termination of Clover | F16: Harrow | G16: Harrow | H16: Harrow (Tines) | I16: =IF(ISBLANK(H16), "", VLOOKUP(H16,Dropdowns_Formulas!C$2:D$100,2,FALSE)) -> 0.2 | J16: 3 | K16: Terminated to plant Winter Wheat, unsure if termination occurred in fall to allow for typical Oct. winter wheat planting
B17: Tile_N_McKee_MRF DRIVE EAST 72AC_Old | C17: Termination | D17: 45560 | E17: Termination | F17: Disk Ripper | G17: Disk | H17: Disk Chisel (Mulch Tiller) | I17: =IF(ISBLANK(H17), "", VLOOKUP(H17,Dropdowns_Formulas!C$2:D$100,2,FALSE)) -> 0.55 | J17: 15
B18: Tile_N_McKee_MRF DRIVE EAST 72AC_Old | C18: Termination | D18: 45560 | E18: Termination | F18: Harrow | G18: Harrow | H18: Harrow (Tines) | I18: =IF(ISBLANK(H18), "", VLOOKUP(H18,Dropdowns_Formulas!C$2:D$100,2,FALSE)) -> 0.2 | J18: 3
B19: Tile_N_McKee_MRF DRIVE WEST 60AC_Old | C19: Pre-Plant | D19: 42638 | E19: Work ground/Termination of Clover | F19: Disk | G19: Disk | H19: Single Disk | I19: =IF(ISBLANK(H19), "", VLOOKUP(H19,Dropdowns_Formulas!C$2:D$100,2,FALSE)) -> 0.45 | J19: 6
B20: Tile_N_McKee_MRF DRIVE WEST 60AC_Old | C20: Pre-Plant | D20: 42638 | E20: Work ground/Termination of Clover | F20: Harrow | G20: Harrow | H20: Harrow (Tines) | I20: =IF(ISBLANK(H20), "", VLOOKUP(H20,Dropdowns_Formulas!C$2:D$100,2,FALSE)) -> 0.2 | J20: 3
B21: Tile_N_McKee_MRF DRIVE WEST 60AC_Old | C21: Termination | D21: 43895 | E21: Termination | F21: Disk Ripper | G21: Disk | H21: Disk Chisel (Mulch Tiller) | I21: =IF(ISBLANK(H21), "", VLOOKUP(H21,Dropdowns_Formulas!C$2:D$100,2,FALSE)) -> 0.55 | J21: 15
B22: Tile_N_McKee_MRF DRIVE WEST 60AC_Old | C22: Termination | D22: 43895 | E22: Termination | F22: Harrow | G22: Harrow | H22: Harrow (Tines) | I22: =IF(ISBLANK(H22), "", VLOOKUP(H22,Dropdowns_Formulas!C$2:D$100,2,FALSE)) -> 0.2 | J22: 3
B23: Tile_N_McKee_MRF DRIVE WEST 60AC_Old | C23: Pre-Plant | D23: 44099 | E23: Work ground/Termination of Clover | F23: Disk | G23: Disk | H23: Single Disk | I23: =IF(ISBLANK(H23), "", VLOOKUP(H23,Dropdowns_Formulas!C$2:D$100,2,FALSE)) -> 0.45 | J23: 6
B24: Tile_N_McKee_MRF DRIVE WEST 60AC_Old | C24: Pre-Plant | D24: 44099 | E24: Work ground/Termination of Clover | F24: Harrow | G24: Harrow | H24: Harrow (Tines) | I24: =IF(ISBLANK(H24), "", VLOOKUP(H24,Dropdowns_Formulas!C$2:D$100,2,FALSE)) -> 0.2 | J24: 3 | K24: 2023-2024 unsure if whole field was terminated before planting TF, small section of field planted in kale
B25: Tile_N_McKee_MRF DRIVE WEST 60AC_Old | C25: Termination | D25: 45721 | E25: Termination | F25: Disk Ripper | G25: Disk | H25: Disk Chisel (Mulch Tiller) | I25: =IF(ISBLANK(H25), "", VLOOKUP(H25,Dropdowns_Formulas!C$2:D$100,2,FALSE)) -> 0.55 | J25: 15
B26: Tile_N_McKee_MRF DRIVE WEST 60AC_Old | C26: Termination | D26: 45721 | E26: Termination | F26: Harrow | G26: Harrow | H26: Harrow (Tines) | I26: =IF(ISBLANK(H26), "", VLOOKUP(H26,Dropdowns_Formulas!C$2:D$100,2,FALSE)) -> 0.2 | J26: 3
B27: Tile_N_McKee_MRF DRIVE WEST 60AC_Old | C27: Pre-Plant | D27: 45772 | E27: Work Ground | F27: Disk | G27: Disk | H27: Single Disk | I27: =IF(ISBLANK(H27), "", VLOOKUP(H27,Dropdowns_Formulas!C$2:D$100,2,FALSE)) -> 0.45 | J27: 6
B28: Tile_N_McKee_MRF DRIVE WEST 60AC_Old | C28: Pre-Plant | D28: 45772 | E28: Work Ground | F28: Harrow | G28: Harrow | H28: Harrow (Tines) | I28: =IF(ISBLANK(H28), "", VLOOKUP(H28,Dropdowns_Formulas!C$2:D$100,2,FALSE)) -> 0.2 | J28: 3
B29: Tile_N_McKee_NOLAS 67AC_New | C29: Termination | D29: 43905 | E29: Termination | F29: Disk Ripper | G29: Disk | H29: Disk Chisel (Mulch Tiller) | I29: =IF(ISBLANK(H29), "", VLOOKUP(H29,Dropdowns_Formulas!C$2:D$100,2,FALSE)) -> 0.55 | J29: 15
B30: Tile_N_McKee_NOLAS 67AC_New | C30: Termination | D30: 43905 | E30: Termination | F30: Harrow | G30: Harrow | H30: Harrow (Tines) | I30: =IF(ISBLANK(H30), "", VLOOKUP(H30,Dropdowns_Formulas!C$2:D$100,2,FALSE)) -> 0.2 | J30: 3
B31: Tile_N_McKee_NOLAS 67AC_New | C31: Pre-Plant | D31: 44099 | E31: Work Ground | F31: Disk | G31: Disk | H31: Single Disk | I31: =IF(ISBLANK(H31), "", VLOOKUP(H31,Dropdowns_Formulas!C$2:D$100,2,FALSE)) -> 0.45 | J31: 6
B32: Tile_N_McKee_NOLAS 67AC_New | C32: Pre-Plant | D32: 44099 | E32: Work Ground | F32: Harrow | G32: Harrow | H32: Harrow (Tines) | I32: =IF(ISBLANK(H32), "", VLOOKUP(H32,Dropdowns_Formulas!C$2:D$100,2,FALSE)) -> 0.2 | J32: 3
B33: Tile_N_McKee_NOLAS 67AC_New | C33: Termination | D33: 45000 | E33: Termination | F33: Disk Ripper | G33: Disk | H33: Disk Chisel (Mulch Tiller) | I33: =IF(ISBLANK(H33), "", VLOOKUP(H33,Dropdowns_Formulas!C$2:D$100,2,FALSE)) -> 0.55 | J33: 15 | K33: PRG - RAD - RC - RC - PRG
B34: Tile_N_McKee_NOLAS 67AC_New | C34: Termination | D34: 45000 | E34: Termination | F34: Harrow | G34: Harrow | H34: Harrow (Tines) | I34: =IF(ISBLANK(H34), "", VLOOKUP(H34,Dropdowns_Formulas!C$2:D$100,2,FALSE)) -> 0.2 | J34: 3
B35: Tile_N_McKee_NOLAS 67AC_New | C35: Pre-Plant | D35: 45925 | E35: Work Ground | F35: Disk | G35: Disk | H35: Single Disk | I35: =IF(ISBLANK(H35), "", VLOOKUP(H35,Dropdowns_Formulas!C$2:D$100,2,FALSE)) -> 0.45 | J35: 6
B36: Tile_N_McKee_NOLAS 67AC_New | C36: Pre-Plant | D36: 45925 | E36: Work Ground | F36: Harrow | G36: Harrow | H36: Harrow (Tines) | I36: =IF(ISBLANK(H36), "", VLOOKUP(H36,Dropdowns_Formulas!C$2:D$100,2,FALSE)) -> 0.2 | J36: 3
B37: Tile_N_McKee_OSBORNE FRONT WEST 40 AC_Untiled | C37: Pre-Plant | D37: 43003 | E37: Work Ground | F37: Disk | G37: Disk | H37: Single Disk | I37: =IF(ISBLANK(H37), "", VLOOKUP(H37,Dropdowns_Formulas!C$2:D$100,2,FALSE)) -> 0.45 | J37: 6
B38: Tile_N_McKee_OSBORNE FRONT WEST 40 AC_Untiled | C38: Pre-Plant | D38: 43003 | E38: Work Ground | F38: Harrow | G38: Harrow | H38: Harrow (Tines) | I38: =IF(ISBLANK(H38), "", VLOOKUP(H38,Dropdowns_Formulas!C$2:D$100,2,FALSE)) -> 0.2 | J38: 3
B39: Tile_N_McKee_OSBORNE FRONT WEST 40 AC_Untiled | C39: Termination | D39: 44270 | E39: Termination | F39: Disk Ripper | G39: Disk | H39: Disk Chisel (Mulch Tiller) | I39: =IF(ISBLANK(H39), "", VLOOKUP(H39,Dropdowns_Formulas!C$2:D$100,2,FALSE)) -> 0.55 | J39: 15
B40: Tile_N_McKee_OSBORNE FRONT WEST 40 AC_Untiled | C40: Termination | D40: 44270 | E40: Harrow | F40: Harrow | G40: Harrow | H40: Harrow (Tines) | I40: =IF(ISBLANK(H40), "", VLOOKUP(H40,Dropdowns_Formulas!C$2:D$100,2,FALSE)) -> 0.2 | J40: 3
...

Sheet Soil_Amendments
A1: Description | B1: Unique Mgt ID | C1: Amendment Category | D1: Amendment Source | E1: Amend Date | F1: Amendment Rate | G1: Amendment Units | H1: Nitrogen added via Amendment | I1: P2O5 added via Amendment | J1: K2O added via Amendment | K1: Water in Amendment | L1: C/N ratio of Amendment | M1: User may add any notes here
A2: Type | B2: <dropdown> | C2: <dropdown> | D2: <dropdown> | E2: <date> | F2: <numeric> | G2: <dropdown> | H2: <numeric> | I2: <numeric> | J2: <numeric> | K2: <numeric> | L2: <numeric> | M2: <character>
A3: Units | B3: NA | C3: NA | D3: NA | E3: MM/DD/YYYY | F3: <user-defined> | G3: NA | H3: <see Column G> | I3: <see Column G> | J3: <see Column G> | K3: % | L3: ratio
B4: MGT_combo | C4: SA_cat | D4: SA_source | E4: SA_date | F4: SA_rate | G4: SA_units | H4: SA_N | I4: SA_P2O5 | J4: SA_K2O | K4: SA_H2O_per | L4: SA_CN | M4: SA_notes

Sheet Animal_Diversity
A1: Description | B1: Unique Mgt ID | C1: Animal Type | D1: Grazing intensity | E1: Animal Count | F1: Animal Start Date | G1: Animal End Date | H1: Animal Unit Months | I1: User may add any notes here
A2: Type | B2: <dropdown> | C2: <dropdown> | D2: <dropdown> | E2: <integer> | F2: <date> | G2: <date> | H2: <numeric> | I2: <character>
A3: Units | B3: NA | C3: NA | D3: NA | E3: head / acre | F3: MM/DD/YYYY | G3: MM/DD/YYYY | H3: NA | I3: NA
B4: MGT_combo | C4: AD_type | D4: AD_intensity | E4: AD_count | F4: AD_start_date | G4: AD_end_date | H4: AD_aum | I4: AD_notes

Sheet Dropdowns_Manual
A1: mgt_states_list | B1: mgt_study_list | C1: mgt_tile_drain_list | D1: mgt_tile_years_list | E1: crop_mix | F1: crop_cat_list | G1: crop_group_list | H1: crop_brassica_list | I1: crop_broadleaf_warm_list | J1: crop_broadleaf_cool_list | K1: crop_grass_warm_list | L1: crop_grass_cool_list | M1: crop_legume_warm_list | N1: crop_legume_cool_list | O1: crop_horticulture_list | P1: crop_saline_list | Q1: crop_all_crops_list | R1: Pasture_Mixed | S1: crop_yield_units_list | T1: crop_term_methods_list | U1: crop_res_mgt | V1: crop_irr_type_list | W1: crop_irr_units | X1: ops_phase_list | Y1: ops_equip_cat_list | Z1: ops_cultivator_list | AA1: ops_disk_list | AB1: ops_harrow_list | AC1: ops_plow_list | AD1: ops_roller_or_packer_list | AE1: ops_rotary_equip_list | AF1: ops_seedbed_prep_list | AG1: ops_soil_conditioner_list | AH1: ops_miscellaneous_list | AI1: ops_equip_list | AJ1: amend_cat_list | AK1: amend_fertilizer_list | AL1: amend_lime_list | AM1: amend_organic_list | AN1: amend_all_amend_list | AO1: amend_units | AP1: ani_type_list | AQ1: ani_intensity_list | AR1: st_texture_list
A2: Alabama | B2: Residue_M | C2: Yes | D2: None | E2: Yes | F2: Annual | G2: All_crops | H2: Canola | I2: Buckwheat | J2: Beets | K2: Bermuda | L2: Barley | M2: Beans, Cluster | N2: Alfalfa | O2: Almond | P2: Alkaligrass | Q2: Alfalfa | R2: Grasses, Cold | S2: lbs/acre | T2: Chemical | U2: baled | V2: Drip | W2: inches | X2: Pre-Plant | Y2: All_equip | Z2: Beet Cultivator | AA2: Bedder (Disk) | AB2: Finishing Harrow | AC2: Bedder (Disk) | AD2: Bed Roller | AE2: Rotary Hoe | AF2: Bed Roller | AG2: Coulter-Chisel | AH2: Crust Buster | AI2: Bed Roller | AJ2: All_amend | AK2: Fertilizer Blend | AL2: Agricultural Lime | AM2: Alfalfa Meal | AN2: Agricultural Lime | AO2: lbs/acre | AP2: Antelope, mature | AQ2: None | AR2: sand
A3: Alaska | B3: Residue_V | C3: No | D3: 0-5 | E3: No | F3: Perennial | G3: Brassica | H3: Mustard | I3: Chicory | J3: Camelina | K3: Big Bluestem | L3: Fescue, Fine | M3: Beans, Mung | N3: Beans, Bell | O3: Apple | P3: Wheatgrass, Intermediate | Q3: Alkaligrass | R3: Grasses, Warm | S3: bushels/acre | T3: Mechanical | U3: chop & flail | V3: Drip, Mobile | W3: cm | X3: Crop Mgt | Y3: Cultivator | Z3: Culti-Mulch Roller | AA3: Bedder Disk-Hipper | AB3: Flex-Tine Harrow | AC3: Bedder Shaper | AD3: Culti-Mulch Roller | AE3: Roterra | AF3: Bedder (Disk) | AG3: Crust Buster | AH3: Cultiweeder | AI3: Bedder (Disk) | AJ3: Fertilizer | AK3: Ammonium Nitrate | AL3: Burnt Lime/Quicklime | AM3: Beef Manure, solid | AN3: Burnt Lime/Quicklime | AO3: tons/acre | AP3: Bison, mature | AQ3: Light | AR3: loamy sand
A4: Arizona | B4: Tile_N | C4: Unsure | D4: 5-10 | F4: Cover | G4: Broadleaf_warm | H4: Rapeseed | I4: Cotton | J4: Carrot | K4: Corn | L4: Fescue, Tall | M4: Cowpea | N4: Beans, Dry | O4: Avocado | P4: Wheatgrass, RS Hybrid | Q4: Almond | R4: Legumes, Cold | S4: kgs/acre | T4: Winter Kill | U4: incorporated | V4: Furrow | W4: mm | X4: Termination | Y4: Disk | Z4: Cultiweeder | AA4: Disk-O-Vator (Discovator) | AB4: Harrow (Tines) | AC4: Chisel Plow | AD4: Culti-Packer Pulverizer | AE4: Roto-Tiller | AF4: Bedder Disk-Hipper | AG4: Culti-Packer Pulverizer | AH4: Do-All | AI4: Bedder Disk-Hipper | AJ4: Lime | AK4: Ammonium Nitrate Phosphate | AL4: Crushed | AM4: Beef Manure, slurry | AN4: Crushed | AO4: kgs/hectare | AP4: Bull | AQ4: Medium | AR4: sandy loam
A5: Arkansas | B5: Tile_S | D5: 11-20 | G5: Broadleaf_cool | H5: Turnip | I5: Cucurbits | J5: Chard | K5: Hay | L5: Fescue, Tall (Forage) | M5: Fenugreek | N5: Beans, Fava | O5: Cottonwoods | P5: Wheatgrass, Slender | Q5: Apple | R5: Legumes, Warm | S5: lbs/hectare | T5: Annual Crop | U5: stubble | V5: Sprinkler, Big Gun | X5: Residue Mgt | Y5: Harrow | Z5: Duckfoot Cultivator | AA5: Disk Border Maker | AB5: Powered Spike Tooth Harrow | AC5: Disk Plow | AD5: Packer | AE5: Roto-Tiller | AF5: Bedder Disk-Row | AG5: Field Conditioner (Scratcher) | AH5: Float | AI5: Bedder Disk-Row | AJ5: Organic | AK5: Ammonium Phosphate Sulphate | AL5: Dolomitic | AM5: Biochar, Biosolids | AN5: Dolomitic | AO5: tonnes/hectare | AP5: Cattle, 1-yr-old | AQ5: Heavy | AR5: loam
A6: California | B6: Tillage | D6: >20 | G6: Grass_warm | H6: Collards | I6: Quinoa | J6: Flax | K6: Haygrazer | L6: Fescue, Tall (Turf) | M6: Pea, Pigeon | N6: Beans, Pinto | O6: Grapes | P6: Wheatgrass, Tall | Q6: Avocado | R6: Brassicas | S6: bushels/hectare | V6: Sprinkler, Linear | Y6: Plow | Z6: Field Cultivator | AA6: Disk Chisel (Mulch Tiller) | AB6: Roller Harrow | AC6: Furrow Diker | AD6: Packer Roller Flat Roller | AE6: Rotovator-Bedder | AF6: Bedder Shaper | AG6: Float | AH6: Leveler | AI6: Bedder Shaper | AK6: Ammonium Polyphosphate | AL6: Hydrated Lime | AM6: Biochar, Manure | AN6: Hydrated Lime | AP6: Cattle, 2-yr-old | AR6: silt loam
A7: Colorado | B7: WV_Hops | G7: Grass_cool | H7: Mustard, Oriental | I7: Safflower | J7: Kale | K7: Millet | L7: Oats | M7: Peanut | N7: Beans, Snap | O7: Orange, Mandarin | P7: Wildrye, Russian | Q7: Barley | R7: Broadleaves, Cold | S7: kgs/hectare | V7: Sprinkler, Pivot | Y7: Roller_or_Packer | Z7: Furrow-Out Cultivator | AA7: Levee-Plow-Disc | AB7: Spike Tooth Harrow | AC7: Furrow-Out Cultivator | AD7: Rice Roller | AF7: Roller Groover | AG7: Hipper | AH7: Paraplow | AI7: Beet Cultivator | AK7: Ammonium Sulfate | AL7: Other | AM7: Biochar, Herbaceous | AN7: Other | AP7: Cow | AR7: silt
A8: Connecticut | B8: MLSH | G8: Legume_warm | H8: Mustard, Yellow | I8: Sugarcane | J8: Meadowfoam | K8: Millet, Foxtail | L8: Oats, Black | M8: Soybean | N8: Chickpeas | O8: Peach | Q8: Beans, Bell | R8: Broadleaves, Warm | V8: None | Y8: Rotary_Equipment | Z8: Marker (Cultivator) | AA8: Offset Disk-Heavy Duty | AB8: Springtooth Harrow | AC8: Lister (Middle-Buster) | AD8: Roller Groover | AF8: Seedbed Roller | AG8: Land Plane-Leveler | AH8: Rowbuck | AI8: Blade 10 Ft | AK8: Ammonium Thiosulphate | AL8: Pellitized Lime | AM8: Biochar, Rice | AN8: Pellitized Lime | AP8: Cow/Calf | AR8: sandy clay loam
A9: Delaware | B9: Unknown | G9: Legume_cool | H9: Mustard, White | I9: Sunflower | J9: Phacelia | K9: Millet, Hay | L9: Reed Canary Grass | M9: Soybean, Double-cropped | N9: Clover | O9: Pear | Q9: Beans, Cluster | Y9: Seedbed_Preparation | Z9: Multi-Weeder | AA9: Offset Disk-Light Duty | AC9: Middle Buster | AD9: Roller Harrow | AG9: Landall | AH9: Sand-Fighter | AI9: Chisel Plow | AK9: Calcium Ammonium Nitrate | AL9: Wet Lime | AM9: Biochar, Wood | AN9: Wet Lime | AP9: Deer, Mule, mature | AR9: clay loam
A10: Florida | G10: Saline | I10: Tomato | J10: Potato | K10: Millet, Pearl | L10: Rye | M10: Soybean, Forage | N10: Clover, Balansa | O10: Walnut | Q10: Beans, Dry | Y10: Soil_Conditioner | Z10: Rod Weeder | AA10: One-Way (Disk Tiller) | AC10: Moldboard Plow Reg | AD10: Seedbed Roller | AG10: Laser Planer | AH10: Triple K | AI10: Coulter-Chisel | AK10: Calcium Nitrate | AM10: Blood, Dried | AN10: Fertilizer Blend | AP10: Deer, White-tailed, mature | AR10: silty clay loam
A11: Georgia | G11: Horticulture | I11: Okra | J11: Radish | K11: Millet, Proso | L11: Rye, Cereal | M11: Sunnhemp | N11: Clover, Berseem | Q11: Beans, Fava | Y11: Miscellaneous | Z11: Rolling Cultivator | AA11: Single Disk | AC11: One-Way (Disk Tiller) | AG11: Leveler | AI11: Crust Buster | AK11: Diammonium Phosphate | AM11: Bone Meal | AN11: Ammonium Nitrate | AP11: Elk, mature | AR11: sandy clay
A12: Hawaii | G12: Pasture_Mixed | J12: Spinach | K12: Miscanthus | L12: Ryegrass | N12: Clover, Crimson | Q12: Beans, Mung | Z12: Row Conditioner | AA12: Tandem Disk Plow | AC12: Paraplow | AG12: Packer | AI12: Culti-Mulch Roller | AK12: Element-N | AM12: Chicken Broiler, solid | AN12: Ammonium Nitrate Phosphate | AP12: Goat, mature | AR12: silty clay
A13: Idaho | J13: Squash, Summer | K13: Sorghum | L13: Ryegrass, Annual | N13: Clover, Kura | Q13: Beans, Pinto | Z13: Row Cultivator | AA13: Tandem Disk Reg | AC13: Stubble-Mulch Plow | AG13: Packer Roller Flat Roller | AI13: Culti-Packer Pulverizer | AK13: Element-S | AM13: Chicken Broiler, slurry | AN13: Ammonium Phosphate Sulphate | AP13: Horse, mature | AR13: clay
A14: Illinois | J14: Strawberries | K14: Sorghum, BMR | L14: Ryegrass, Perennial | N14: Clover, Persian | Q14: Beans, Snap | Z14: Rubber-Wheel Weed Puller | AA14: Vertical Disk | AC14: Subsoil Chisel Plow | AG14: Power Mulcher | AI14: Culti-Weeder | AK14: ESN 44-0-0 (polymer coated granules) | AM14: Chicken Layer, solid | AN14: Ammonium Polyphosphate | AP14: Kid, 1-yr-old
A15: Indiana | K15: Sorghum, Forage | L15: Timothy Grass | N15: Clover, Red | Q15: Beets | Z15: Triple K | AC15: Subsoiler-Bedder Hip-Rip | AG15: Roller Groover | AI15: Deep Ripper-Subsoiler | AK15: Monoammonium Phosphate | AM15: Chicken Layer, slurry | AN15: Ammonium Sulfate | AP15: Lamb, 1-yr-old
A16: Iowa | K16: Sorghum, Grain | L16: Triticale | N16: Clover, Sweet | Q16: Bermuda | AC16: Tandem Disk Plow | AG16: Rolling Cultivator | AI16: Disk-O-Vator (Discovator) | AK16: Potash | AM16: Composted Manure, solid | AN16: Ammonium Thiosulphate | AP16: Sheep, Bighorn, mature
A17: Kansas | K17: Sorghum, Sudan | L17: Wheat | N17: Clover, White | Q17: Big Bluestem | AC17: Tandem Disk Reg | AG17: Soil Finisher | AI17: Disk Border Maker | AK17: Potassium Carbonate | AM17: Dairy Manure, solid | AN17: Calcium Ammonium Nitrate | AP17: Sheep, mature
A18: Kentucky | K18: Sudangrass | L18: Wheat, Spring | N18: Clover, Yellow_Blossom | Q18: Buckwheat | AC18: V-Ripper | AI18: Disk Chisel (Mulch Tiller) | AK18: Potassium Chloride | AM18: Dairy Manure, slurry | AN18: Calcium Nitrate
A19: Louisiana | K19: Switchgrass | L19: Wheat, Winter | N19: Lentil | Q19: Camelina | AI19: Disk Plow | AK19: Potassium Nitrate | AM19: Feather Meal | AN19: Diammonium Phosphate
A20: Maine | K20: Switchgrass, Summer | N20: Lentil, Winter | Q20: Canola | AI20: Disk Ripper | AK20: Urea | AM20: Fish Emulsion | AN20: Element-N
A21: Maryland | K21: Switchgrass, Sunburst | N21: Lespedeza, Roundhead | Q21: Carrot | AI21: Duckfoot Cultivator | AK21: Urea AgrotainPlus | AM21: Fish Scrap | AN21: Element-S
A22: Massachusetts | K22: Teff | N22: Lupin | Q22: Chard | AI22: Field Conditioner (Scratcher) | AK22: Urea Ammonium Nitrate | AM22: Guano | AN22: ESN 44-0-0 (polymer coated granules)
A23: Michigan | N23: Medic | Q23: Chickpeas | AI23: Field Cultivator | AK23: Urea Ammonium Phosphate | AM23: Horse Manure, solid | AN23: Monoammonium Phosphate
A24: Minnesota | N24: Pea | Q24: Chicory | AI24: Finishing Harrow | AM24: Other Manure, solid | AN24: Potash
A25: Mississippi | N25: Pea, Austrian Winter | Q25: Clover | AI25: Flex-Tine Harrow | AM25: Sheep Manure, solid | AN25: Potassium Carbonate
A26: Missouri | N26: Pea, Field | Q26: Clover, Balansa | AI26: Float | AM26: Soybean Meal | AN26: Potassium Chloride
A27: Montana | N27: Sainfoin | Q27: Clover, Berseem | AI27: Furrow Diker | AM27: Swine Manure, solid | AN27: Potassium Nitrate
A28: Nebraska | N28: Trefoil, Birdsfoot | Q28: Clover, Crimson | AI28: Furrow-Out Cultivator | AM28: Swine Manure, slurry | AN28: Urea
A29: Nevada | N29: Vetch | Q29: Clover, Kura | AI29: Harrow (Tines) | AN29: Urea AgrotainPlus
A30: New Hampshire | N30: Vetch, Hairy | Q30: Clover, Persian | AI30: Hipper | AN30: Urea Ammonium Nitrate
A31: New Jersey | Q31: Clover, Red | AI31: Land Plane-Leveler | AN31: Urea Ammonium Phosphate
A32: New Mexico | Q32: Clover, Sweet | AI32: Landall, Do-All | AN32: Alfalfa Meal
A33: New York | Q33: Clover, White | AI33: Laser Planer | AN33: Beef Manure, solid
A34: North Carolina | Q34: Clover, Yellow_Blossom | AI34: Levee-Plow-Disk | AN34: Beef Manure, slurry
A35: North Dakota | Q35: Collards | AI35: Leveler | AN35: Biochar, Biosolids
A36: Ohio | Q36: Corn | AI36: Lister (Middle-Buster) | AN36: Biochar, Manure
A37: Oklahoma | Q37: Cotton | AI37: Marker (Cultivator) | AN37: Biochar, Herbaceous
A38: Oregon | Q38: Cottonwoods | AI38: Middle Buster | AN38: Biochar, Rice
A39: Pennsylvania | Q39: Cowpea | AI39: Moldboard Plow Reg | AN39: Biochar, Wood
A40: Rhode Island | Q40: Cucurbits | AI40: Multi-Weeder | AN40: Blood, Dried
...

Sheet Soil_Test
A1: Description | B1: Unique Mgt ID | C1: Soil Testing Laboratory | D1: Soil Sample Date | E1: Soil Test Depth | F1: Soil Texture Class | G1: Soil Organic Carbon | H1: Soil Organic Matter | I1: Soil pH | J1: Soil Electrical Conductivity | K1: Add any notes here
A2: Type | B2: <dropdown> | C2: <character> | D2: <character> | E2: <integer> | F2: <dropdown> | G2: <numeric> | H2: <numeric> | I2: <numeric> | J2: <numeric> | K2: <character>
A3: Units | B3: NA | C3: NA | D3: MM/DD/YYYY | E3: inches | F3: NA | G3: % | H3: % | I3: % | J3: dS/m | K3: NA
B4: MGT_combo | C4: ST_test_lab | D4: ST_test_date | E4: ST_test_depth | F4: ST_texture | G4: ST_SOC | H4: ST_OM | I4: ST_pH | J4: ST_EC | K4: ST_notes

Sheet Dropdowns_Formulas
A1: Users | B1: MgtUnitID | C1: ops_equip | D1: ME
A2: =IF(ISBLANK(User_Info!B5),"",LOWER(User_Info!B5)&"."&LOWER(User_Info!C5)) -> zach.mckee | B2: =IF(ISBLANK(Mgt_Unit!$C5),"",Mgt_Unit!$C5) -> Tile_N_McKee_MANZI NW CORNER 15AC_Old | C2: Bed Roller | D2: 0.25
A3: =IF(ISBLANK(User_Info!B6),"",LOWER(User_Info!B6)&"."&LOWER(User_Info!C6)) | B3: =IF(ISBLANK(Mgt_Unit!$C6),"",Mgt_Unit!$C6) -> Tile_N_McKee_MANZI PIVOT 115AC_Old | C3: Bedder (Disk) | D3: 0.55
A4: =IF(ISBLANK(User_Info!B7),"",LOWER(User_Info!B7)&"."&LOWER(User_Info!C7)) | B4: =IF(ISBLANK(Mgt_Unit!$C7),"",Mgt_Unit!$C7) -> Tile_N_McKee_MRF DRIVE EAST 72AC_Old | C4: Bedder Disk-Hipper | D4: 0.65
A5: =IF(ISBLANK(User_Info!B8),"",LOWER(User_Info!B8)&"."&LOWER(User_Info!C8)) | B5: =IF(ISBLANK(Mgt_Unit!$C8),"",Mgt_Unit!$C8) -> Tile_N_McKee_MRF DRIVE WEST 60AC_Old | C5: Bedder Disk-Row | D5: 0.85
A6: =IF(ISBLANK(User_Info!B9),"",LOWER(User_Info!B9)&"."&LOWER(User_Info!C9)) | B6: =IF(ISBLANK(Mgt_Unit!$C9),"",Mgt_Unit!$C9) -> Tile_N_McKee_NOLAS 67AC_New | C6: Bedder Shaper | D6: 0.55
A7: =IF(ISBLANK(User_Info!B10),"",LOWER(User_Info!B10)&"."&LOWER(User_Info!C10)) | B7: =IF(ISBLANK(Mgt_Unit!$C10),"",Mgt_Unit!$C10) -> Tile_N_McKee_OSBORNE FRONT WEST 40 AC_Untiled | C7: Beet Cultivator | D7: 0.25
A8: =IF(ISBLANK(User_Info!B11),"",LOWER(User_Info!B11)&"."&LOWER(User_Info!C11)) | B8: =IF(ISBLANK(Mgt_Unit!$C11),"",Mgt_Unit!$C11) -> Tile_N_McKee_ZORA ANN N OF RD 45AC_Untiled | C8: Blade 10 Ft | D8: 0.25
A9: =IF(ISBLANK(User_Info!B12),"",LOWER(User_Info!B12)&"."&LOWER(User_Info!C12)) | B9: =IF(ISBLANK(Mgt_Unit!$C12),"",Mgt_Unit!$C12) -> Tile_N_McKee_ZORA ANN N OF RD BTM 60AC_Untiled | C9: Chisel Plow | D9: 0.3
A10: =IF(ISBLANK(User_Info!B13),"",LOWER(User_Info!B13)&"."&LOWER(User_Info!C13)) | B10: =IF(ISBLANK(Mgt_Unit!$C13),"",Mgt_Unit!$C13) -> Tile_N_McKee_ZORA ANN S OF RD BTM 65AC_Untiled | C10: Coulter-Chisel | D10: 0.5
A11: =IF(ISBLANK(User_Info!B14),"",LOWER(User_Info!B14)&"."&LOWER(User_Info!C14)) | B11: =IF(ISBLANK(Mgt_Unit!$C14),"",Mgt_Unit!$C14) -> Tile_N_McKee_ZORA ANN S OF RD 53AC_New | C11: Crust Buster | D11: 0.1
A12: =IF(ISBLANK(User_Info!B15),"",LOWER(User_Info!B15)&"."&LOWER(User_Info!C15)) | B12: =IF(ISBLANK(Mgt_Unit!#REF!),"",Mgt_Unit!#REF!) -> #REF! | C12: Culti-Mulch Roller | D12: 0.25
A13: =IF(ISBLANK(User_Info!B16),"",LOWER(User_Info!B16)&"."&LOWER(User_Info!C16)) | B13: =IF(ISBLANK(Mgt_Unit!#REF!),"",Mgt_Unit!#REF!) -> #REF! | C13: Culti-Packer Pulverizer | D13: 0.35
A14: =IF(ISBLANK(User_Info!B17),"",LOWER(User_Info!B17)&"."&LOWER(User_Info!C17)) | B14: =IF(ISBLANK(Mgt_Unit!$C15),"",Mgt_Unit!$C15) | C14: Culti-Weeder | D14: 0.3
A15: =IF(ISBLANK(User_Info!B18),"",LOWER(User_Info!B18)&"."&LOWER(User_Info!C18)) | B15: =IF(ISBLANK(Mgt_Unit!$C16),"",Mgt_Unit!$C16) | C15: Deep Ripper-Subsoiler | D15: 0.25
A16: =IF(ISBLANK(User_Info!B19),"",LOWER(User_Info!B19)&"."&LOWER(User_Info!C19)) | B16: =IF(ISBLANK(Mgt_Unit!$C17),"",Mgt_Unit!$C17) | C16: Disk-O-Vator (Discovator) | D16: 0.5
A17: =IF(ISBLANK(User_Info!B20),"",LOWER(User_Info!B20)&"."&LOWER(User_Info!C20)) | B17: =IF(ISBLANK(Mgt_Unit!$C18),"",Mgt_Unit!$C18) | C17: Disk Border Maker | D17: 0.55
A18: =IF(ISBLANK(User_Info!B21),"",LOWER(User_Info!B21)&"."&LOWER(User_Info!C21)) | B18: =IF(ISBLANK(Mgt_Unit!$C19),"",Mgt_Unit!$C19) | C18: Disk Chisel (Mulch Tiller) | D18: 0.55
A19: =IF(ISBLANK(User_Info!B22),"",LOWER(User_Info!B22)&"."&LOWER(User_Info!C22)) | B19: =IF(ISBLANK(Mgt_Unit!$C20),"",Mgt_Unit!$C20) | C19: Disk Plow | D19: 0.85
A20: =IF(ISBLANK(User_Info!B23),"",LOWER(User_Info!B23)&"."&LOWER(User_Info!C23)) | B20: =IF(ISBLANK(Mgt_Unit!$C21),"",Mgt_Unit!$C21) | C20: Duckfoot Cultivator | D20: 0.55
A21: =IF(ISBLANK(User_Info!B24),"",LOWER(User_Info!B24)&"."&LOWER(User_Info!C24)) | B21: =IF(ISBLANK(Mgt_Unit!$C22),"",Mgt_Unit!$C22) | C21: Field Conditioner (Scratcher) | D21: 0.1
A22: =IF(ISBLANK(User_Info!B25),"",LOWER(User_Info!B25)&"."&LOWER(User_Info!C25)) | B22: =IF(ISBLANK(Mgt_Unit!$C23),"",Mgt_Unit!$C23) | C22: Field Cultivator | D22: 0.3
A23: =IF(ISBLANK(User_Info!B26),"",LOWER(User_Info!B26)&"."&LOWER(User_Info!C26)) | B23: =IF(ISBLANK(Mgt_Unit!$C24),"",Mgt_Unit!$C24) | C23: Finishing Harrow | D23: 0.55
A24: =IF(ISBLANK(User_Info!B27),"",LOWER(User_Info!B27)&"."&LOWER(User_Info!C27)) | B24: =IF(ISBLANK(Mgt_Unit!$C25),"",Mgt_Unit!$C25) | C24: Flex-Tine Harrow | D24: 0.2
A25: =IF(ISBLANK(User_Info!B28),"",LOWER(User_Info!B28)&"."&LOWER(User_Info!C28)) | B25: =IF(ISBLANK(Mgt_Unit!$C26),"",Mgt_Unit!$C26) | C25: Float | D25: 0.1
... A53: =IF(ISBLANK(User_Info!B56),"",LOWER(User_Info!B56)&"."&LOWER(User_Info!C56)) | B53: =IF(ISBLANK(Mgt_Unit!$C54),"",Mgt_Unit!$C54) | C53: Rolling Cultivator | D53: 0.5
C54: Rotary Hoe | D54: 0.1
C55: Roterra | D55: 0.8
C56: Roto-Tiller | D56: 0.8
C57: Rotovator-Bedder | D57: 0.8
C58: Row Conditioner | D58: 0.5
C59: Row Cultivator | D59: 0.25
C60: Rowbuck | D60: 0.7
C61: Rubber-Wheel Weed Puller | D61: 0.35
C62: Sand-Fighter | D62: 0.7
C63: Seedbed Roller | D63: 0.7
C64: Single Disk | D64: 0.45
C65: Soil Finisher | D65: 0.55
... C82: Vertical Disk | D82: 0.25

Sheet Crop Order 
A1: MCKEE RIVER FARMS
A2: FIELD HISTORY
A4: FIELDS | B4: NOLAS 67AC | C4: ZORA ANN S OF RD BTM 65AC | D4: ZORA ANN N OF RD BTM 60AC | E4: ZORA ANN S OF RD 53AC | F4: ZORA ANN N OF RD 45AC | G4: MANZI PIVOT 115AC | H4: MANZI NW CORNER 15AC | I4: MRF DRIVE WEST 60AC | J4: MRF DRIVE EAST 72AC | K4: OSBORNE FRONT WEST 40 AC
A5: 2016 | B5: PRG | C5: TF | D5: TF | E5: TF | F5: TF | G5: N/A | H5: N/A | I5: RC | J5: PRG | K5: PEAS/RC
A6: 2017 | B6: PRG | C6: TF | D6: TF | E6: TF | F6: TF | G6: N/A | H6: N/A | I6: PRG | J6: RAD | K6: RC
A7: 2018 | B7: PRG | C7: RC | D7: TF | E7: RAD | F7: TF | G7: RAD | H7: TF | I7: PRG | J7: RC | K7: PRG
A8: 2019 | B8: PRG | C8: RC | D8: TF | E8: RC | F8: TF | G8: RC | H8: TF | I8: PRG | J8: RC | K8: PRG
A9: 2020 | B9: RADISH | C9: PRG | D9: TF | E9: RC | F9: TF | G9: RC | H9: TF | I9: RAD | J9: PRG | K9: PRG
A10: 2021 | B10: PRG | C10: PRG | D10: TF | E10: TF | F10: TF | G10: RC | H10: TF | I10: PRG | J10: PRG | K10: RC
A11: 2022 | B11: PRG | C11: TF | D11: TF | E11: TF | F11: RAD | G11: TF | H11: TF | I11: PRG | J11: PRG | K11: RC
A12: 2023 | B12: RADISH | C12: TF | D12: RAD | E12: TF | F12: RC | G12: TF | H12: TF | I12: PRG | J12: PRG | K12: RC
A13: 2024 | B13: RC | C13: TF | D13: RC | E13: TF | F13: RC | G13: TF | H13: TF | I13: KALE (10 AC) | J13: PRG | K13: PRG
A14: 2025 | B14: RC | C14: TF | D14: RC | E14: TF | F14: PRG | G14: TF | H14: TF | I14: TF | J14: WHEAT | K14: PRG
A15: 2026 | B15: PRG | C15: WHEAT | D15: FALLOW | E15: WHEAT | F15: PRG | G15: TF | H15: TF | I15: TF | J15: GARLIC | K15: WHEAT
A18: FIELDS | B18: 2016 | C18: 2017 | D18: 2018 | E18: 2019 | F18: 2020 | G18: 2021 | H18: 2022 | I18: 2023 | J18: 2024 | K18: 2025 | L18: 2026
A19: NOLAS 67AC | B19: PRG | C19: PRG | D19: PRG | E19: PRG | F19: RADISH | G19: PRG | H19: PRG | I19: RADISH | J19: RC | K19: RC | L19: PRG
A20: ZORA ANN S OF RD BTM 65AC | B20: TF | C20: TF | D20: RC | E20: RC | F20: PRG | G20: PRG | H20: TF | I20: TF | J20: TF | K20: TF | L20: WHEAT
A21: ZORA ANN N OF RD BTM 60AC | B21: TF | C21: TF | D21: TF | E21: TF | F21: TF | G21: TF | H21: TF | I21: RAD | J21: RC | K21: RC | L21: FALLOW
A22: ZORA ANN S OF RD 53AC | B22: TF | C22: TF | D22: RAD | E22: RC | F22: RC | G22: TF | H22: TF | I22: TF | J22: TF | K22: TF | L22: WHEAT
A23: ZORA ANN N OF RD 45AC | B23: TF | C23: TF | D23: TF | E23: TF | F23: TF | G23: TF | H23: RAD | I23: RC | J23: RC | K23: PRG | L23: PRG
A24: MANZI PIVOT 115AC | B24: N/A | C24: N/A | D24: RAD | E24: RC | F24: RC | G24: RC | H24: TF | I24: TF | J24: TF | K24: TF | L24: TF
A25: MANZI NW CORNER 15AC | B25: N/A | C25: N/A | D25: TF | E25: TF | F25: TF | G25: TF | H25: TF | I25: TF | J25: TF | K25: TF | L25: TF
A26: MRF DRIVE WEST 60AC | B26: RC | C26: PRG | D26: PRG | E26: PRG | F26: RAD | G26: PRG | H26: PRG | I26: PRG | J26: KALE (10 AC) | K26: TF | L26: TF
A27: MRF DRIVE EAST 72AC | B27: PRG | C27: RAD | D27: RC | E27: RC | F27: PRG | G27: PRG | H27: PRG | I27: PRG | J27: PRG | K27: WHEAT | L27: GARLIC
A28: OSBORNE FRONT WEST 40 AC | B28: PEAS/RC | C28: RC | D28: PRG | E28: PRG | F28: PRG | G28: RC | H28: RC | I28: RC | J28: PRG | K28: PRG | L28: WHEAT

Sheet Field list
A1: study | B1: field_code | C1: farm | D1: field | E1: field_id | F1: date_sampled | G1: latitude | H1: longitude | I1: location link | J1: name | K1: phone | L1: email | M1: soil | N1: Treatment | O1: crop_at_sampling | P1: stand_age | Q1: FIELDS | S1: 2016 | T1: 2017 | U1: 2018 | V1: 2019 | W1: 2020 | X1: 2021 | Y1: 2022 | Z1: 2023 | AA1: 2024 | AB1: 2025 | AC1: 2026 | AD1: Irrigation? | AE1: Tile install date? | AF1: Soil samples? | AG1: Lime? | AH1: Compost? | AI1: Grazing?
A2: Tile.N | B2: MNW | C2: McKee | D2: McKee | E2: Mansies NW Corner | F2: 45049 | G2: 44.79301 | H2: -123.31054 | I2: https://maps.app.goo.gl/cWtq9bmFjgvPFWwp6 | J2: Zach McKee | K2: 503-949-3116 | L2: zmckeez@gmail.com | M2: Woodburn | N2: Old | O2: Fescue | Q2: MANZI NW CORNER 15AC | R2: Irrigated only in establishment | S2: N/A | T2: N/A | U2: TF Forage | V2: TF | W2: TF | X2: TF | Y2: TF | Z2: TF | AA2: TF | AB2: TF | AC2: TF
A3: Tile.N | B3: MSP | C3: McKee | D3: McKee | E3: Mansies Pivot | F3: 45049 | G3: 44.79246 | H3: -123.30809 | I3: https://maps.app.goo.gl/VRvgC88Ti3Ux45km8 | J3: Zach McKee | K3: 503-949-3116 | L3: zmckeez@gmail.com | M3: Coburg | N3: Old | O3: Fescue | Q3: MANZI PIVOT 115AC | R3: Shot in spring, and 2x in fall | S3: N/A | T3: N/A | U3: RAD | V3: RC | W3: RC | X3: RC (TF was underseed into RC in spring) RC harvested, irrigated | Y3: TF | Z3: TF | AA3: TF | AB3: TF | AC3: TF
A4: Tile.N | B4: MDE | C4: McKee | D4: McKee | E4: MMR Driveway East | F4: 45055 | G4: 44.79417 | H4: -123.26835 | I4: https://maps.app.goo.gl/eE2cLz5ew5LMsQhu5 | J4: Zach McKee | K4: 503-949-3116 | L4: zmckeez@gmail.com | M4: Woodburn | N4: Old | O4: PRG | Q4: MRF DRIVE EAST 72AC | R4: Pre-irrigated Garlic, none for wheat, Once or twice on PR before 2023 | S4: PRG | T4: RAD | U4: RC | V4: RC | W4: PRG | X4: PRG | Y4: PRG (terminated and re-planted) | Z4: PRG | AA4: PRG | AB4: WHEAT | AC4: GARLIC
A5: Tile.N | B5: MDW | C5: McKee | D5: McKee | E5: MMR Driveway West | F5: 45055 | G5: 44.79489 | H5: -123.26968 | I5: https://maps.app.goo.gl/dSVTi3XsjQhWPExv5 | J5: Zach McKee | K5: 503-949-3116 | L5: zmckeez@gmail.com | M5: Woodburn | N5: Old | O5: PRG | Q5: MRF DRIVE WEST 60AC | R5: 2025 spring, irrigated Kale, mostly not irrigated before 2023, irrigated PRG one of the years | S5: RC | T5: PRG | U5: PRG | V5: PRG | W5: RAD | X5: PRG | Y5: PRG | Z5: PRG | AA5: Wheat(KALE on 10 AC) | AB5: TF | AC5: TF
A6: Tile.N | B6: NOL | C6: McKee | D6: McKee | E6: Nolas | F6: 45046 | G6: 44.80825 | H6: -123.31007 | I6: https://maps.app.goo.gl/jUNLuvjZJktna66P6 | J6: Zach McKee | K6: 503-949-3116 | L6: zmckeez@gmail.com | M6: Carlton | N6: New? | O6: Clover | Q6: NOLAS 67AC | R6: Has irrigation, one shot late spring for Radish, one shot for PRG in fall only, 1.5" | S6: PRG | T6: PRG | U6: PRG | V6: PRG | W6: RADISH | X6: PRG | Y6: PRG | Z6: RADISH | AA6: RC | AB6: RC | AC6: PRG
A7: Tile.N | B7: OSB | C7: McKee | D7: McKee | E7: Osborne | F7: 45056 | G7: 44.79181 | H7: -123.32575 | I7: https://maps.app.goo.gl/8kC7WnP3ovaQf11K9 | J7: Zach McKee | K7: 503-949-3116 | L7: zmckeez@gmail.com | M7: Woodburn | N7: Untiled | O7: Red Clover | Q7: OSBORNE FRONT WEST 40 AC | R7: none | S7: PEAS/RC | T7: RC | U7: PRG | V7: PRG | W7: PRG | X7: RC | Y7: RC | Z7: RC | AA7: PRG | AB7: PRG | AC7: WHEAT
A8: Tile.N | B8: ZAN | C8: McKee | D8: McKee | E8: Zoran North of Road | F8: 45056 | G8: 44.79163 | H8: -123.33122 | I8: https://maps.app.goo.gl/ziTFnmrKfiFiX5AE9 | J8: Zach McKee | K8: 503-949-3116 | L8: zmckeez@gmail.com | M8: Woodburn | N8: Untiled | O8: Red Clover | Q8: ZORA ANN N OF RD 45AC | R8: none | S8: TF | T8: TF | U8: TF | V8: TF | W8: TF | X8: Tfsprayed out in fall, ripped 2x, then disk, let sit over winter | Y8: RAD | Z8: RC | AA8: RC | AB8: PRG | AC8: PRG
A9: Tile.N | B9: ZNB | C9: McKee | D9: McKee | E9: Zoran North of Road Bottom | F9: 45044 | G9: 44.79673 | H9: -123.33139 | I9: https://maps.app.goo.gl/pD8EYNkcP8SyJdCo8 | J9: Zach McKee | K9: 503-949-3116 | L9: zmckeez@gmail.com | M9: Coburg | N9: Untiled | O9: Fallow | Q9: ZORA ANN N OF RD BTM 60AC | R9: none | S9: TF | T9: TF | U9: TF | V9: TF | W9: TF | X9: TF | Y9: TF Sprayed out in november, let sit, worked with disk 2x in spring (march), then harrowed | Z9: RAD | AA9: RC | AB9: RC | AC9: FALLOW
A10: Tile.N | B10: ZSB | C10: McKee | D10: McKee | E10: Zoran South of Road Bottom | F10: 45046 | G10: 44.7869 | H10: -123.33071 | I10: https://maps.app.goo.gl/ayzWcHCT2Vx2DKBz9 | J10: Zach McKee | K10: 503-949-3116 | L10: zmckeez@gmail.com | M10: Coburg | N10: Untiled | O10: Fallow | Q10: ZORA ANN S OF RD BTM 65AC | R10: None | S10: TF | T10: TF spray in fall, rip 2x, plow, then let sit., disk 1x then harrow in spring | U10: RC | V10: RC | W10: PRG | X10: PRG | Y10: Radish+RC spring planted, RC didn't make it | Z10: TF (spring plant | AA10: TF | AB10: TF | AC10: TF
A11: Tile.N | B11: ZAS | C11: McKee | D11: McKee | E11: Zoran South of Road | F11: 45048 | G11: 44.79082 | H11: -123.33104 | I11: https://maps.app.goo.gl/uwgvM6nvtHLgYoKv7 | J11: Zach McKee | K11: 503-949-3116 | L11: zmckeez@gmail.com | M11: Woodburn | N11: New | O11: Fescue | Q11: ZORA ANN S OF RD 53AC | R11: None | S11: TF | T11: TF spray in fall, rip 2x, plow, then let sit., disk 1x then harrow in spring | U11: RAD | V11: RC | W11: RC | X11: TF | Y11: TF | Z11: TF | AA11: TF | AB11: TF | AC11: WHEAT
A12: Tile.N | B12: MBM | C12: McKee | D12: McKee | E12: MMR Bottom Middle | F12: 45048 | G12: 44.78739 | H12: -123.25412 | I12: https://maps.app.goo.gl/5Uctgs6X663hsGM3A | J12: Zach McKee | K12: 503-949-3116 | L12: zmckeez@gmail.com | M12: Coburg | N12: Old | O12: Fescue
A13: res.V | C13: McKee | D13: McKee | F13: 2019 | G13: 45.178803 | H13: -123.20508 | I13: https://maps.app.goo.gl/AsaGCTo1DPr8o8JY8 | J13: Zach McKee | K13: 503-949-3116 | L13: zmckeez@gmail.com | M13: dayton | N13: baled | O13: Fescue | P13: 6
R15: irrigation shot is 1.5 inches | U15: RAD=Radish
U16: RC=Red Clover
U17: TF=Tall Fescue
F18: Questrion | I18: Answer | U18: PRG=Perennial Ryegrass
F19: Data not available because you didn't manage the field? | I19: corn for 20 years | M19: dairy | N19: applied lots of manure | O19: best yielding fields
F20: winter or spring wheat? | I20: winter wheat
F21: where in the field was the Kale? | I21: south west corner only | M21: square block | N21: gps point was in Kale area
F22: Was this a mix or rotation? | I22: RC underseed into peas | M22: disaster | N22: Planted at the same time in the fall | O22: peas were terrible | P22: RC was beautiful | Q22: RC was harvested second year only
F23: what is your fallow process?
F24: tile installation dates? | I24: RC harvested 2025, will plant TF this spring
F25: missing fields | I25: Will find Bottom middle
F26: clarify? | I26: 60 ac not yet plantedto radish

Sheet Standard practices
A1: Crop | C1: Pre-plant prep | D1: Planting date | E1: Fertilizer at planting | F1: Fall fertilizer | G1: Spring fertilizer | H1: Irrigation | I1: Harvest date | J1: Average yield | K1: Residue | L1: Termination date | M1: Post termination soil work
A2: TF | B2: mostly spring planted | C2: Following RC, leave clover through winter as long as possible, Terlinate by working in the spring with a disk (6" deep) (only) 1x, maybe 2x, harrow (2-3" deep) 2-3x, sit for 10 days minimum to get sprout, plant then spray roudup 5-6 days later | D2: Early may | E2: 10-34-0 at 7gal to the acre for the no-till drill, | F2: 30 units N, 10 P 140K, 80S | G2: 155units N, 15K, 12S | H2: varies | I2: July swath early july | J2: 1500 lb/ac clean | K2: all baled | L2: spray out in september, after some rain/re-growth, spray with Roundup. Let sit over winter, after depends on next crop. Rip 2x with disk Ripper Plow, leave fallow, disk and harrow for the spring
A3: PRG | B3: all fall planted with carbon drill | C3: disked 2x (after radish or clover) harrowed, let sprout, spray, then carbon plant | D3: end of october | E3: some fert in carbon | F3: 30 units N, 10 P 140K, 80S | G3: 155units N, 15K, 12S (sometimes a little more N | I3: Mid-july | J3: 1700lb/ac | K3: all baled | L3: wait for re-growth fall, spray out in spring feb or march, disk 1 -2 x then harrow
A4: RC | B4: usually underseed with radish | D4: end of march- early april | E4: 10-34-0 at 7gal to the acre for the no-till drill, | F4: none | G4: no additional fertilizer for the redclover | H4: second or third year, when blloming in spring 1 shot | I4: swath august, combine september september
A5: Radish | D5: end of march- early april | E5: 10-34-0 at 7gal to the acre for the no-till drill,, 18-11-20-3S 0.2Mg, 0.2 B 340lb dry pre-plant | F5: none | H5: generally no | I5: september
A6: Peas | B6: worked in spring, dixed 2x and harrowed, RC+Peas | D6: end of march- early april
A7: Wheat | D7: 46310
A8: Fallow
A9: Kale
C11: only disk rip fescue
