Workbook
Name All_amend: Dropdowns_Manual!$AP$2:$AP$82
Name All_crops: Dropdowns_Manual!$S$2:$S$162
Name All_equip: Dropdowns_Manual!$AK$2:$AK$200
Name AmendType: Dropdowns_Manual!$AL$2:$AL$19
Name AnimalDiv_GrazIntensity: Dropdowns_Manual!$AR$2:$AR$16
Name AnimalType: Dropdowns_Manual!$AQ$2:$AQ$65
Name Brassica: Dropdowns_Manual!$J$2:$J$51
Name Broadleaf_cool: Dropdowns_Manual!$L$2:$L$51
Name Broadleaf_warm: Dropdowns_Manual!$K$2:$K$51
Name crop_mix: Dropdowns_Manual!$F$2:$F$8
Name CropCategory: Dropdowns_Manual!$H$3:$H$19
Name CropDiv_YieldUnits: Dropdowns_Manual!$U$2:$U$26
Name CropIrrUnits: Dropdowns_Manual!$Y$2:$Y$15
Name CropResMgt: Dropdowns_Manual!$W$2:$W$37
Name CropType: Dropdowns_Manual!$G$2:$G$21
Name CropUnit: Dropdowns_Formulas!$C$2:$C$114
Name Cultivator: Dropdowns_Manual!$AB$2:$AB$200
Name Disk: Dropdowns_Manual!$AC$2:$AC$200
Name Fallow: Dropdowns_Manual!$I$2
Name Fertilizer: Dropdowns_Manual!$AM$2:$AM$79
Name Grass_cool: Dropdowns_Manual!$N$2:$N$52
Name Grass_warm: Dropdowns_Manual!$M$2:$M$51
Name Harrow: Dropdowns_Manual!$AD$2:$AD$200
Name Horticulture: Dropdowns_Manual!$Q$2:$Q$53
Name Implement: Dropdowns_Manual!$AK$2:$AK$99
Name IrrType: Dropdowns_Manual!$X$2:$X$32
Name Legume_cool: Dropdowns_Manual!$P$2:$P$51
Name Legume_warm: Dropdowns_Manual!$O$2:$O$51
Name Lime: Dropdowns_Manual!$AN$2:$AN$24
Name Mgt_tile_years: Dropdowns_Manual!$E$2:$E$7
Name Mgt_TileDrain: Dropdowns_Manual!$D$2:$D$12
Name MgtUnit: Dropdowns_Formulas!$B$2:$B$200
Name MgtUnit_Study: Dropdowns_Manual!$C$2:$C$200
Name Miscellaneous: Dropdowns_Manual!$AJ$2:$AJ$200
Name OpsMgt: Dropdowns_Manual!$Z$2:$Z$25
Name Organic: Dropdowns_Manual!$AO$2:$AO$76
Name Other: Dropdowns_Manual!$T$2:$T$64
Name Pasture_Mixed: Dropdowns_Manual!$T$3:$T$200
Name Plow: Dropdowns_Manual!$AE$2:$AE$200
Name Roller_or_Packer: Dropdowns_Manual!$AF$2:$AF$100
Name Rotary_Equipment: Dropdowns_Manual!$AG$2:$AG$100
Name Saline: Dropdowns_Manual!$R$2:$R$50
Name Seedbed_Prep: Dropdowns_Manual!$AH$2:$AH$100
Name Soil_Conditioner: Dropdowns_Manual!$AI$2:$AI$100
Name SoilDist_OpsEquipCat: Dropdowns_Manual!$AA$2:$AA$11
Name States: Dropdowns_Manual!$B$2:$B$51
Name TermMethod: Dropdowns_Manual!$V$2:$V$54
Name User_Perm: Dropdowns_Manual!$A$2:$A$3
Name Users: Dropdowns_Formulas!$A$2:$A$200

Sheet User_Info
A1: Description | B1: User Name | C1: User Permissions | D1: User Password | E1: First Name | F1: Last Name | G1: Email | H1: Phone Number
A2: Type | B2: <character> | C2: <auto-generated> | E2: <character> | F2: <character> | G2: <character> | H2: <character>
A3: Units | B3: NA | C3: NA | D3: NA | E3: NA | F3: NA | G3: NA | H3: NA
B4: user_name | C4: user_perm | D4: user_password | E4: user_first | F4: user_last | G4: user_email | H4: user_phone
B5: jennifer.moore | D5: shmi | E5: jennifer | F5: moore
C6: =IF(ISBLANK(B6),"", "guest")
C7: =IF(ISBLANK(B7),"", "guest")
C8: =IF(ISBLANK(B8),"", "guest")
C9: =IF(ISBLANK(B9),"", "guest")
C10: =IF(ISBLANK(B10),"", "guest")
C11: =IF(ISBLANK(B11),"", "guest")
C12: =IF(ISBLANK(B12),"", "guest")
C13: =IF(ISBLANK(B13),"", "guest")
C14: =IF(ISBLANK(B14),"", "guest")
C15: =IF(ISBLANK(B15),"", "guest")
C16: =IF(ISBLANK(B16),"", "guest")
C17: =IF(ISBLANK(B17),"", "guest")
... C504: =IF(ISBLANK(B504),"", "guest")
C505: admin
C506: =IF(ISBLANK(B506),"", "guest")
C507: =IF(ISBLANK(B507),"", "guest")
C508: =IF(ISBLANK(B508),"", "guest")
C509: =IF(ISBLANK(B509),"", "guest")
C510: =IF(ISBLANK(B510),"", "guest")
C511: =IF(ISBLANK(B511),"", "guest")
C512: =IF(ISBLANK(B512),"", "guest")
C513: =IF(ISBLANK(B513),"", "guest")
C514: =IF(ISBLANK(B514),"", "guest")
C515: =IF(ISBLANK(B515),"", "guest")
C516: =IF(ISBLANK(B516),"", "guest")
C517: =IF(ISBLANK(B517),"", "guest")
... C1004: =IF(ISBLANK(B1004),"", "guest")

Sheet Mgt_Unit
A1: Description | B1: Name of User | C1: Excel Unique ID | D1: Study | E1: Farm/Owner | F1: Field Name | G1: Latitude | H1: Longitude | I1: State | J1: County | K1: Field Polygon | L1: Name of field or treatment ID | M1: Tile Drainage | N1: Number of years under tile drainage | O1: User may add any notes here
A2: Type | B2: <dropdown> | C2: <auto-generated> | D2: <character> | E2: <character> | F2: <character> | G2: <numeric> | H2: <numeric> | I2: <dropdown> | J2: <character> | K2: <geojson> | L2: <character> | M2: <dropdown> | N2: <dropdown> | O2: <character>
A3: Units | B3: NA | C3: NA | D3: NA | E3: NA | F3: NA | G3: dec degrees | H3: dec degrees | I3: NA | J3: NA | K3: NA | L3: NA | M3: NA | N3: NA | O3: NA
B4: user_name | C4: MGT_combo | D4: MGT_study | E4: MGT_farm | F4: MGT_field | G4: MGT_lat | H4: MGT_lon | I4: MGT_state | J4: MGT_county | K4: MGT_polygon | L4: MGT_trt | M4: MGT_tile_drain | N4: MGT_tile_years | O4: MGT_notes
B5: jennifer.moore | C5: =IF(ISBLANK(D5), "", CONCATENATE(D5,E5,"_",F5,"_",L5)) -> NAPESHM_MXAG01_1 | D5: NAPESHM | F5: MXAG01 | G5: 22.162556 | H5: -102.29133 | I5: Aguascalientes | L5: 1 | M5: Unsure | N5: Unsure | O5: Pabellon de Arteaga, AGU
B6: jennifer.moore | C6: =IF(ISBLANK(D6), "", CONCATENATE(D6,E6,"_",F6,"_",L6)) -> NAPESHM_MXAG01_2 | D6: NAPESHM | F6: MXAG01 | G6: 22.162556 | H6: -102.29133 | I6: Aguascalientes | L6: 2 | M6: Unsure | N6: Unsure | O6: Pabellon de Arteaga, AGU
B7: jennifer.moore | C7: =IF(ISBLANK(D7), "", CONCATENATE(D7,E7,"_",F7,"_",L7)) -> NAPESHM_MXAG01_3 | D7: NAPESHM | F7: MXAG01 | G7: 22.162556 | H7: -102.29133 | I7: Aguascalientes | L7: 3 | M7: Unsure | N7: Unsure | O7: Pabellon de Arteaga, AGU
B8: jennifer.moore | C8: =IF(ISBLANK(D8), "", CONCATENATE(D8,E8,"_",F8,"_",L8)) -> NAPESHM_MXAG01_4 | D8: NAPESHM | F8: MXAG01 | G8: 22.162556 | H8: -102.29133 | I8: Aguascalientes | L8: 4 | M8: Unsure | N8: Unsure | O8: Pabellon de Arteaga, AGU
B9: jennifer.moore | C9: =IF(ISBLANK(D9), "", CONCATENATE(D9,E9,"_",F9,"_",L9)) -> NAPESHM_MXAG01_5 | D9: NAPESHM | F9: MXAG01 | G9: 22.162556 | H9: -102.29133 | I9: Aguascalientes | L9: 5 | M9: Unsure | N9: Unsure | O9: Pabellon de Arteaga, AGU
B10: jennifer.moore | C10: =IF(ISBLANK(D10), "", CONCATENATE(D10,E10,"_",F10,"_",L10)) -> NAPESHM_MXEM01_6 | D10: NAPESHM | F10: MXEM01 | G10: 19.531968 | H10: -98.847405 | I10: Estado de Mexico | L10: 6 | M10: Unsure | N10: Unsure | O10: Texcoco I
B11: jennifer.moore | C11: =IF(ISBLANK(D11), "", CONCATENATE(D11,E11,"_",F11,"_",L11)) -> NAPESHM_MXEM01_7 | D11: NAPESHM | F11: MXEM01 | G11: 19.531968 | H11: -98.847405 | I11: Estado de Mexico | L11: 7 | M11: Unsure | N11: Unsure | O11: Texcoco I
B12: jennifer.moore | C12: =IF(ISBLANK(D12), "", CONCATENATE(D12,E12,"_",F12,"_",L12)) -> NAPESHM_MXEM01_8 | D12: NAPESHM | F12: MXEM01 | G12: 19.531968 | H12: -98.847405 | I12: Estado de Mexico | L12: 8 | M12: Unsure | N12: Unsure | O12: Texcoco I
B13: jennifer.moore | C13: =IF(ISBLANK(D13), "", CONCATENATE(D13,E13,"_",F13,"_",L13)) -> NAPESHM_MXEM01_9 | D13: NAPESHM | F13: MXEM01 | G13: 19.531968 | H13: -98.847405 | I13: Estado de Mexico | L13: 9 | M13: Unsure | N13: Unsure | O13: Texcoco I
B14: jennifer.moore | C14: =IF(ISBLANK(D14), "", CONCATENATE(D14,E14,"_",F14,"_",L14)) -> NAPESHM_MXEM01_10 | D14: NAPESHM | F14: MXEM01 | G14: 19.531968 | H14: -98.847405 | I14: Estado de Mexico | L14: 10 | M14: Unsure | N14: Unsure | O14: Texcoco I
B15: jennifer.moore | C15: =IF(ISBLANK(D15), "", CONCATENATE(D15,E15,"_",F15,"_",L15)) -> NAPESHM_MXEM01_11 | D15: NAPESHM | F15: MXEM01 | G15: 19.531968 | H15: -98.847405 | I15: Estado de Mexico | L15: 11 | M15: Unsure | N15: Unsure | O15: Texcoco I
B16: jennifer.moore | C16: =IF(ISBLANK(D16), "", CONCATENATE(D16,E16,"_",F16,"_",L16)) -> NAPESHM_MXEM01_12 | D16: NAPESHM | F16: MXEM01 | G16: 19.531968 | H16: -98.847405 | I16: Estado de Mexico | L16: 12 | M16: Unsure | N16: Unsure | O16: Texcoco I
... B188: jennifer.moore | C188: =IF(ISBLANK(D188), "", CONCATENATE(D188,E188,"_",F188,"_",L188)) -> NAPESHM_USCO01_184 | D188: NAPESHM | F188: USCO01 | G188: 37.271117 | H188: -102.2048 | I188: Colorado | L188: 184 | M188: Unsure | N188: Unsure | O188: Walsh Dryland Agroecosystem Project
B189: jennifer.moore | C189: NAPESHM_USCO01_185 | D189: NAPESHM | F189: USCO01 | G189: 37.271117 | H189: -102.2048 | I189: Colorado | L189: 185 | M189: Unsure | N189: Unsure | O189: Walsh Dryland Agroecosystem Project
B190: jennifer.moore | C190: NAPESHM_USCO01_186 | D190: NAPESHM | F190: USCO01 | G190: 37.271117 | H190: -102.2048 | I190: Colorado | L190: 186 | M190: Unsure | N190: Unsure | O190: Walsh Dryland Agroecosystem Project
B191: jennifer.moore | C191: NAPESHM_USCO01_187 | D191: NAPESHM | F191: USCO01 | G191: 37.271117 | H191: -102.2048 | I191: Colorado | L191: 187 | M191: Unsure | N191: Unsure | O191: Walsh Dryland Agroecosystem Project
B192: jennifer.moore | C192: =IF(ISBLANK(D192), "", CONCATENATE(D192,E192,"_",F192,"_",L192)) -> NAPESHM_USCO01_188 | D192: NAPESHM | F192: USCO01 | G192: 37.271117 | H192: -102.2048 | I192: Colorado | L192: 188 | M192: Unsure | N192: Unsure | O192: Walsh Dryland Agroecosystem Project
B193: jennifer.moore | C193: =IF(ISBLANK(D193), "", CONCATENATE(D193,E193,"_",F193,"_",L193)) -> NAPESHM_USCO01_189 | D193: NAPESHM | F193: USCO01 | G193: 37.271117 | H193: -102.2048 | I193: Colorado | L193: 189 | M193: Unsure | N193: Unsure | O193: Walsh Dryland Agroecosystem Project
B194: jennifer.moore | C194: =IF(ISBLANK(D194), "", CONCATENATE(D194,E194,"_",F194,"_",L194)) -> NAPESHM_USCO01_190 | D194: NAPESHM | F194: USCO01 | G194: 37.271117 | H194: -102.2048 | I194: Colorado | L194: 190 | M194: Unsure | N194: Unsure | O194: Walsh Dryland Agroecosystem Project
B195: jennifer.moore | C195: =IF(ISBLANK(D195), "", CONCATENATE(D195,E195,"_",F195,"_",L195)) -> NAPESHM_USCO01_191 | D195: NAPESHM | F195: USCO01 | G195: 37.271117 | H195: -102.2048 | I195: Colorado | L195: 191 | M195: Unsure | N195: Unsure | O195: Walsh Dryland Agroecosystem Project
B196: jennifer.moore | C196: =IF(ISBLANK(D196), "", CONCATENATE(D196,E196,"_",F196,"_",L196)) -> NAPESHM_USCO01_192 | D196: NAPESHM | F196: USCO01 | G196: 37.271117 | H196: -102.2048 | I196: Colorado | L196: 192 | M196: Unsure | N196: Unsure | O196: Walsh Dryland Agroecosystem Project
B197: jennifer.moore | C197: =IF(ISBLANK(D197), "", CONCATENATE(D197,E197,"_",F197,"_",L197)) -> NAPESHM_USCO01_193 | D197: NAPESHM | F197: USCO01 | G197: 37.271117 | H197: -102.2048 | I197: Colorado | L197: 193 | M197: Unsure | N197: Unsure | O197: Walsh Dryland Agroecosystem Project
B198: jennifer.moore | C198: =IF(ISBLANK(D198), "", CONCATENATE(D198,E198,"_",F198,"_",L198)) -> NAPESHM_USCO02_194 | D198: NAPESHM | F198: USCO02 | G198: 39.299374 | H198: -102.52024 | I198: Colorado | L198: 194 | M198: Unsure | N198: Unsure | O198: Stratton Dryland Agroecosystem Project
B199: jennifer.moore | C199: =IF(ISBLANK(D199), "", CONCATENATE(D199,E199,"_",F199,"_",L199)) -> NAPESHM_USCO02_195 | D199: NAPESHM | F199: USCO02 | G199: 39.299374 | H199: -102.52024 | I199: Colorado | L199: 195 | M199: Unsure | N199: Unsure | O199: Stratton Dryland Agroecosystem Project
B200: jennifer.moore | C200: =IF(ISBLANK(D200), "", CONCATENATE(D200,E200,"_",F200,"_",L200)) -> NAPESHM_USCO02_196 | D200: NAPESHM | F200: USCO02 | G200: 39.299374 | H200: -102.52024 | I200: Colorado | L200: 196 | M200: Unsure | N200: Unsure | O200: Stratton Dryland Agroecosystem Project
B201: jennifer.moore | C201: =IF(ISBLANK(D201), "", CONCATENATE(D201,E201,"_",F201,"_",L201)) -> NAPESHM_USCO02_197 | D201: NAPESHM | F201: USCO02 | G201: 39.299374 | H201: -102.52024 | I201: Colorado | L201: 197 | M201: Unsure | N201: Unsure | O201: Stratton Dryland Agroecosystem Project
B202: jennifer.moore | C202: =IF(ISBLANK(D202), "", CONCATENATE(D202,E202,"_",F202,"_",L202)) -> NAPESHM_USCO02_198 | D202: NAPESHM | F202: USCO02 | G202: 39.299374 | H202: -102.52024 | I202: Colorado | L202: 198 | M202: Unsure | N202: Unsure | O202: Stratton Dryland Agroecosystem Project
B203: jennifer.moore | C203: =IF(ISBLANK(D203), "", CONCATENATE(D203,E203,"_",F203,"_",L203)) -> NAPESHM_USCO02_199 | D203: NAPESHM | F203: USCO02 | G203: 39.299374 | H203: -102.52024 | I203: Colorado | L203: 199 | M203: Unsure | N203: Unsure | O203: Stratton Dryland Agroecosystem Project
... B512: jennifer.moore | C512: =IF(ISBLANK(D512), "", CONCATENATE(D512,E512,"_",F512,"_",L512)) -> NAPESHM_USWY01_508 | D512: NAPESHM | F512: USWY01 | G512: 41.196621 | H512: -104.91112 | I512: Wyoming | L512: 508 | M512: Unsure | N512: Unsure | O512: USDA-ARS Cheyenne, WY East Unit
C513: =IF(ISBLANK(D513), "", CONCATENATE(D513,E513,"_",F513,"_",L513))
C514: =IF(ISBLANK(D514), "", CONCATENATE(D514,E514,"_",F514,"_",L514))
C515: =IF(ISBLANK(D515), "", CONCATENATE(D515,E515,"_",F515,"_",L515))
C516: =IF(ISBLANK(D516), "", CONCATENATE(D516,E516,"_",F516,"_",L516))
C517: =IF(ISBLANK(D517), "", CONCATENATE(D517,E517,"_",F517,"_",L517))
C518: =IF(ISBLANK(D518), "", CONCATENATE(D518,E518,"_",F518,"_",L518))
C519: =IF(ISBLANK(D519), "", CONCATENATE(D519,E519,"_",F519,"_",L519))
...

Sheet Crop_Diversity
A1: Description | B1: Name of User | C1: Unique Mgt ID | D1: Unique Identifier | E1: Crop Sequence Number | F1: Crop Mixture | G1: Crop category | H1: Crop Functional Group | I1: Crop Name | J1: Crop Planting Date | K1: Annual or PerennialHarvest Date | L1: Perennial and Cover Crops Termination Date | M1: Percent residue removed | N1: Residue Management | O1: Yield | P1: Crop Yield Units | Q1: Irrigation category | R1: Total Annual irrigation | S1: User may add any notes here
A2: Type | B2: <autofill> | C2: <dropdown> | D2: <autofill> | E2: <integer> | F2: <dropdown> | G2: <dropdown> | H2: <dropdown> | I2: <dropdown> | J2: <date> | K2: <date> | L2: <date> | M2: <numeric> | N2: <dropdown> | O2: <numeric> | P2: <dropdown> | Q2: <dropdown> | R2: <numeric> | S2: <character>
A3: Units | B3: NA | C3: NA | D3: NA | E3: NA | F3: NA | G3: NA | H3: NA | I3: NA | J3: MM/DD/YYYY | K3: MM/DD/YYYY | L3: MM/DD/YYYY | M3: <user-defined> | N3: NA | O3: <user-defined> | P3: NA | Q3: NA | R3: inches
B4: user_name | C4: MGT_combo | D4: CD_id | E4: CD_seq_num | F4: CD_mix | G4: CD_cat | H4: CD_group | I4: CD_name | J4: CD_plant_date | K4: CD_harv_date | L4: CD_term_date | M4: CD_per_res | N4: CD_res_mgt | O4: CD_yield | P4: CD_yield_units | Q4: CD_irr_cat | R4: CD_irr_amt | S4: CD_notes
B5: =IF(ISNUMBER(MATCH(C5, Mgt_Unit!$C$5:$C$1018, 0)), INDEX(Mgt_Unit!$B$5:$B$1018, MATCH(C5, Mgt_Unit!$C$5:$C$1018, 0)), "") -> jennifer.moore | C5: NAPESHM_MXAG01_1 | E5: 1 | F5: yes | G5: cash | H5: Grass_cool | I5: Triticale | K5: 43144 | M5: 75
B6: =IF(ISNUMBER(MATCH(C6, Mgt_Unit!$C$5:$C$1018, 0)), INDEX(Mgt_Unit!$B$5:$B$1018, MATCH(C6, Mgt_Unit!$C$5:$C$1018, 0)), "") -> jennifer.moore | C6: NAPESHM_MXAG01_1 | E6: 1 | F6: yes | G6: cash | H6: Legume_cool | I6: Vetch, Common | K6: 43144 | M6: 75
B7: =IF(ISNUMBER(MATCH(C7, Mgt_Unit!$C$5:$C$1018, 0)), INDEX(Mgt_Unit!$B$5:$B$1018, MATCH(C7, Mgt_Unit!$C$5:$C$1018, 0)), "") -> jennifer.moore | C7: NAPESHM_MXAG01_1 | E7: 2 | F7: no | G7: cash | H7: Grass_warm | I7: Corn | J7: 43244 | K7: 43378 | M7: 95
B8: =IF(ISNUMBER(MATCH(C8, Mgt_Unit!$C$5:$C$1018, 0)), INDEX(Mgt_Unit!$B$5:$B$1018, MATCH(C8, Mgt_Unit!$C$5:$C$1018, 0)), "") -> jennifer.moore | C8: NAPESHM_MXAG01_1 | E8: 3 | F8: yes | G8: cash | H8: Grass_cool | I8: Triticale | J8: 43404
B9: =IF(ISNUMBER(MATCH(C9, Mgt_Unit!$C$5:$C$1018, 0)), INDEX(Mgt_Unit!$B$5:$B$1018, MATCH(C9, Mgt_Unit!$C$5:$C$1018, 0)), "") -> jennifer.moore | C9: NAPESHM_MXAG01_1 | E9: 3 | F9: yes | G9: cash | H9: Legume_cool | I9: Vetch, Common | J9: 43404
B10: =IF(ISNUMBER(MATCH(C10, Mgt_Unit!$C$5:$C$1018, 0)), INDEX(Mgt_Unit!$B$5:$B$1018, MATCH(C10, Mgt_Unit!$C$5:$C$1018, 0)), "") -> jennifer.moore | C10: NAPESHM_MXAG01_2 | E10: 1 | F10: yes | G10: cash | H10: Grass_cool | I10: Triticale | K10: 43144 | M10: 75
B11: =IF(ISNUMBER(MATCH(C11, Mgt_Unit!$C$5:$C$1018, 0)), INDEX(Mgt_Unit!$B$5:$B$1018, MATCH(C11, Mgt_Unit!$C$5:$C$1018, 0)), "") -> jennifer.moore | C11: NAPESHM_MXAG01_2 | E11: 1 | F11: yes | G11: cash | H11: Legume_cool | I11: Vetch, Common | K11: 43144 | M11: 75
B12: =IF(ISNUMBER(MATCH(C12, Mgt_Unit!$C$5:$C$1018, 0)), INDEX(Mgt_Unit!$B$5:$B$1018, MATCH(C12, Mgt_Unit!$C$5:$C$1018, 0)), "") -> jennifer.moore | C12: NAPESHM_MXAG01_2 | E12: 2 | F12: no | G12: cash | H12: Grass_warm | I12: Corn | J12: 43244 | K12: 43378 | M12: 70
B13: =IF(ISNUMBER(MATCH(C13, Mgt_Unit!$C$5:$C$1018, 0)), INDEX(Mgt_Unit!$B$5:$B$1018, MATCH(C13, Mgt_Unit!$C$5:$C$1018, 0)), "") -> jennifer.moore | C13: NAPESHM_MXAG01_2 | E13: 3 | F13: yes | G13: cash | H13: Grass_cool | I13: Triticale | J13: 43404
B14: =IF(ISNUMBER(MATCH(C14, Mgt_Unit!$C$5:$C$1018, 0)), INDEX(Mgt_Unit!$B$5:$B$1018, MATCH(C14, Mgt_Unit!$C$5:$C$1018, 0)), "") -> jennifer.moore | C14: NAPESHM_MXAG01_2 | E14: 3 | F14: yes | G14: cash | H14: Legume_cool | I14: Vetch, Common | J14: 43404
B15: =IF(ISNUMBER(MATCH(C15, Mgt_Unit!$C$5:$C$1018, 0)), INDEX(Mgt_Unit!$B$5:$B$1018, MATCH(C15, Mgt_Unit!$C$5:$C$1018, 0)), "") -> jennifer.moore | C15: NAPESHM_MXAG01_3 | E15: 1 | F15: yes | G15: cash | H15: Grass_cool | I15: Triticale | K15: 43144 | M15: 75
B16: =IF(ISNUMBER(MATCH(C16, Mgt_Unit!$C$5:$C$1018, 0)), INDEX(Mgt_Unit!$B$5:$B$1018, MATCH(C16, Mgt_Unit!$C$5:$C$1018, 0)), "") -> jennifer.moore | C16: NAPESHM_MXAG01_3 | E16: 1 | F16: yes | G16: cash | H16: Legume_cool | I16: Vetch, Common | K16: 43144 | M16: 75
B17: =IF(ISNUMBER(MATCH(C17, Mgt_Unit!$C$5:$C$1018, 0)), INDEX(Mgt_Unit!$B$5:$B$1018, MATCH(C17, Mgt_Unit!$C$5:$C$1018, 0)), "") -> jennifer.moore | C17: NAPESHM_MXAG01_3 | E17: 2 | F17: no | G17: cash | H17: Grass_warm | I17: Corn | J17: 43244 | K17: 43378 | M17: 95
B18: =IF(ISNUMBER(MATCH(C18, Mgt_Unit!$C$5:$C$1018, 0)), INDEX(Mgt_Unit!$B$5:$B$1018, MATCH(C18, Mgt_Unit!$C$5:$C$1018, 0)), "") -> jennifer.moore | C18: NAPESHM_MXAG01_3 | E18: 3 | F18: yes | G18: cash | H18: Grass_cool | I18: Triticale | J18: 43404
B19: =IF(ISNUMBER(MATCH(C19, Mgt_Unit!$C$5:$C$1018, 0)), INDEX(Mgt_Unit!$B$5:$B$1018, MATCH(C19, Mgt_Unit!$C$5:$C$1018, 0)), "") -> jennifer.moore | C19: NAPESHM_MXAG01_3 | E19: 3 | F19: yes | G19: cash | H19: Legume_cool | I19: Vetch, Common | J19: 43404
B20: =IF(ISNUMBER(MATCH(C20, Mgt_Unit!$C$5:$C$1018, 0)), INDEX(Mgt_Unit!$B$5:$B$1018, MATCH(C20, Mgt_Unit!$C$5:$C$1018, 0)), "") -> jennifer.moore | C20: NAPESHM_MXAG01_4 | E20: 1 | F20: yes | G20: cash | H20: Grass_cool | I20: Triticale | K20: 43144 | M20: 75
B21: =IF(ISNUMBER(MATCH(C21, Mgt_Unit!$C$5:$C$1018, 0)), INDEX(Mgt_Unit!$B$5:$B$1018, MATCH(C21, Mgt_Unit!$C$5:$C$1018, 0)), "") -> jennifer.moore | C21: NAPESHM_MXAG01_4 | E21: 1 | F21: yes | G21: cash | H21: Legume_cool | I21: Vetch, Common | K21: 43144 | M21: 75
B22: =IF(ISNUMBER(MATCH(C22, Mgt_Unit!$C$5:$C$1018, 0)), INDEX(Mgt_Unit!$B$5:$B$1018, MATCH(C22, Mgt_Unit!$C$5:$C$1018, 0)), "") -> jennifer.moore | C22: NAPESHM_MXAG01_4 | E22: 2 | F22: no | G22: cash | H22: Grass_warm | I22: Corn | J22: 43244 | K22: 43378 | M22: 95
B23: =IF(ISNUMBER(MATCH(C23, Mgt_Unit!$C$5:$C$1018, 0)), INDEX(Mgt_Unit!$B$5:$B$1018, MATCH(C23, Mgt_Unit!$C$5:$C$1018, 0)), "") -> jennifer.moore | C23: NAPESHM_MXAG01_4 | E23: 3 | F23: yes | G23: cash | H23: Grass_cool | I23: Triticale | J23: 43404
B24: =IF(ISNUMBER(MATCH(C24, Mgt_Unit!$C$5:$C$1018, 0)), INDEX(Mgt_Unit!$B$5:$B$1018, MATCH(C24, Mgt_Unit!$C$5:$C$1018, 0)), "") -> jennifer.moore | C24: NAPESHM_MXAG01_4 | E24: 3 | F24: yes | G24: cash | H24: Legume_cool | I24: Vetch, Common | J24: 43404
B25: =IF(ISNUMBER(MATCH(C25, Mgt_Unit!$C$5:$C$1018, 0)), INDEX(Mgt_Unit!$B$5:$B$1018, MATCH(C25, Mgt_Unit!$C$5:$C$1018, 0)), "") -> jennifer.moore | C25: NAPESHM_MXAG01_5 | E25: 1 | F25: yes | G25: cash | H25: Grass_cool | I25: Triticale | K25: 43144 | M25: 75
B26: =IF(ISNUMBER(MATCH(C26, Mgt_Unit!$C$5:$C$1018, 0)), INDEX(Mgt_Unit!$B$5:$B$1018, MATCH(C26, Mgt_Unit!$C$5:$C$1018, 0)), "") -> jennifer.moore | C26: NAPESHM_MXAG01_5 | E26: 1 | F26: yes | G26: cash | H26: Legume_cool | I26: Vetch, Common | K26: 43144 | M26: 75
B27: =IF(ISNUMBER(MATCH(C27, Mgt_Unit!$C$5:$C$1018, 0)), INDEX(Mgt_Unit!$B$5:$B$1018, MATCH(C27, Mgt_Unit!$C$5:$C$1018, 0)), "") -> jennifer.moore | C27: NAPESHM_MXAG01_5 | E27: 2 | F27: no | G27: cash | H27: Grass_warm | I27: Corn | J27: 43244 | K27: 43378 | M27: 70
B28: =IF(ISNUMBER(MATCH(C28, Mgt_Unit!$C$5:$C$1018, 0)), INDEX(Mgt_Unit!$B$5:$B$1018, MATCH(C28, Mgt_Unit!$C$5:$C$1018, 0)), "") -> jennifer.moore | C28: NAPESHM_MXAG01_5 | E28: 3 | F28: yes | G28: cash | H28: Grass_cool | I28: Triticale | J28: 43404
B29: =IF(ISNUMBER(MATCH(C29, Mgt_Unit!$C$5:$C$1018, 0)), INDEX(Mgt_Unit!$B$5:$B$1018, MATCH(C29, Mgt_Unit!$C$5:$C$1018, 0)), "") -> jennifer.moore | C29: NAPESHM_MXAG01_5 | E29: 3 | F29: yes | G29: cash | H29: Legume_cool | I29: Vetch, Common | J29: 43404
B30: =IF(ISNUMBER(MATCH(C30, Mgt_Unit!$C$5:$C$1018, 0)), INDEX(Mgt_Unit!$B$5:$B$1018, MATCH(C30, Mgt_Unit!$C$5:$C$1018, 0)), "") -> jennifer.moore | C30: NAPESHM_MXEM01_10 | E30: 1 | F30: no | G30: cash | H30: Grass_cool | I30: Wheat, Spring | J30: 43244 | K30: 43368 | M30: 0
B31: =IF(ISNUMBER(MATCH(C31, Mgt_Unit!$C$5:$C$1018, 0)), INDEX(Mgt_Unit!$B$5:$B$1018, MATCH(C31, Mgt_Unit!$C$5:$C$1018, 0)), "") -> jennifer.moore | C31: NAPESHM_MXEM01_10 | E31: 2 | F31: no | G31: cash | H31: Grass_warm | I31: Corn | J31: 43608 | K31: 43789 | M31: 0
B32: =IF(ISNUMBER(MATCH(C32, Mgt_Unit!$C$5:$C$1018, 0)), INDEX(Mgt_Unit!$B$5:$B$1018, MATCH(C32, Mgt_Unit!$C$5:$C$1018, 0)), "") -> jennifer.moore | C32: NAPESHM_MXEM01_11 | E32: 1 | F32: no | G32: cash | H32: Grass_cool | I32: Wheat, Spring | J32: 43244 | K32: 43368 | M32: 75
B33: =IF(ISNUMBER(MATCH(C33, Mgt_Unit!$C$5:$C$1018, 0)), INDEX(Mgt_Unit!$B$5:$B$1018, MATCH(C33, Mgt_Unit!$C$5:$C$1018, 0)), "") -> jennifer.moore | C33: NAPESHM_MXEM01_11 | E33: 2 | F33: no | G33: cash | H33: Grass_warm | I33: Corn | J33: 43608 | K33: 43789 | M33: 95
B34: =IF(ISNUMBER(MATCH(C34, Mgt_Unit!$C$5:$C$1018, 0)), INDEX(Mgt_Unit!$B$5:$B$1018, MATCH(C34, Mgt_Unit!$C$5:$C$1018, 0)), "") -> jennifer.moore | C34: NAPESHM_MXEM01_12 | E34: 1 | F34: no | G34: cash | H34: Grass_cool | I34: Wheat, Spring | J34: 43244 | K34: 43368 | M34: 0
B35: =IF(ISNUMBER(MATCH(C35, Mgt_Unit!$C$5:$C$1018, 0)), INDEX(Mgt_Unit!$B$5:$B$1018, MATCH(C35, Mgt_Unit!$C$5:$C$1018, 0)), "") -> jennifer.moore | C35: NAPESHM_MXEM01_12 | E35: 2 | F35: no | G35: cash | H35: Grass_warm | I35: Corn | J35: 43608 | K35: 43789 | M35: 0
B36: =IF(ISNUMBER(MATCH(C36, Mgt_Unit!$C$5:$C$1018, 0)), INDEX(Mgt_Unit!$B$5:$B$1018, MATCH(C36, Mgt_Unit!$C$5:$C$1018, 0)), "") -> jennifer.moore | C36: NAPESHM_MXEM01_13 | E36: 1 | F36: no | G36: cash | H36: Grass_cool | I36: Wheat, Spring | J36: 43244 | K36: 43368 | M36: 75
B37: =IF(ISNUMBER(MATCH(C37, Mgt_Unit!$C$5:$C$1018, 0)), INDEX(Mgt_Unit!$B$5:$B$1018, MATCH(C37, Mgt_Unit!$C$5:$C$1018, 0)), "") -> jennifer.moore | C37: NAPESHM_MXEM01_13 | E37: 2 | F37: no | G37: cash | H37: Grass_warm | I37: Corn | J37: 43608 | K37: 43789 | M37: 95
B38: =IF(ISNUMBER(MATCH(C38, Mgt_Unit!$C$5:$C$1018, 0)), INDEX(Mgt_Unit!$B$5:$B$1018, MATCH(C38, Mgt_Unit!$C$5:$C$1018, 0)), "") -> jennifer.moore | C38: NAPESHM_MXEM01_14 | E38: 1 | F38: no | G38: cash | H38: Grass_warm | I38: Corn | J38: 43243 | K38: 43424 | M38: 30
B39: =IF(ISNUMBER(MATCH(C39, Mgt_Unit!$C$5:$C$1018, 0)), INDEX(Mgt_Unit!$B$5:$B$1018, MATCH(C39, Mgt_Unit!$C$5:$C$1018, 0)), "") -> jennifer.moore | C39: NAPESHM_MXEM01_14 | E39: 2 | F39: no | G39: cash | H39: Grass_cool | I39: Wheat, Spring | J39: 43609 | K39: 43733 | M39: 75
B40: =IF(ISNUMBER(MATCH(C40, Mgt_Unit!$C$5:$C$1018, 0)), INDEX(Mgt_Unit!$B$5:$B$1018, MATCH(C40, Mgt_Unit!$C$5:$C$1018, 0)), "") -> jennifer.moore | C40: NAPESHM_MXEM01_15 | E40: 1 | F40: no | G40: cash | H40: Grass_cool | I40: Wheat, Spring | J40: 43244 | K40: 43368 | M40: 75
...

Sheet Soil_Disturbance
A1: Description | B1: Name of User | C1: Unique Mgt & Crop Combo | D1: Unique Identifier | E1: Plant phase operation was performed during | F1: Date operation was performed | G1: Operation Goal (free form) | H1: Common name for piece of equipment | I1: Equipment category | J1: Equipment name | K1: Proportion of soil affected | L1: Depth of soil affected | M1: User may add any notes here
A2: Type | B2: <autofill> | C2: <dropdown> | D2: <autofill> | E2: <dropdown> | F2: <date> | G2: <character> | H2: <character> | I2: <dropdown> | J2: <dropdown> | K2: <numeric> | L2: <numeric> | M2: <character>
A3: Units | B3: NA | C3: NA | D3: NA | E3: NA | F3: MM/DD/YYYY | G3: NA | H3: NA | I3: NA | J3: NA | K3: proportion | L3: inches | M3: NA
B4: user_name | C4: MGT_combo | D4: SD_id | E4: SD_phase | F4: SD_date | G4: SD_goal | H4: SD_name | I4: SD_equip_cat | J4: SD_equip | K4: SD_mixeff | L4: SD_depth | M4: SD_notes
B5: =IF(ISNUMBER(MATCH(C5, Mgt_Unit!$C$5:$C$1018, 0)), INDEX(Mgt_Unit!$B$5:$B$1018, MATCH(C5, Mgt_Unit!$C$5:$C$1018, 0)), "") -> jennifer.moore | C5: NAPESHM_MXAG01_1 | E5: disturbance | F5: 43242 | J5: disc harrow | K5: 39
B6: =IF(ISNUMBER(MATCH(C6, Mgt_Unit!$C$5:$C$1018, 0)), INDEX(Mgt_Unit!$B$5:$B$1018, MATCH(C6, Mgt_Unit!$C$5:$C$1018, 0)), "") -> jennifer.moore | C6: NAPESHM_MXAG01_1 | E6: disturbance | F6: 43244 | J6: planter, double disk opnr | K6: 2.4
B7: =IF(ISNUMBER(MATCH(C7, Mgt_Unit!$C$5:$C$1018, 0)), INDEX(Mgt_Unit!$B$5:$B$1018, MATCH(C7, Mgt_Unit!$C$5:$C$1018, 0)), "") -> jennifer.moore | C7: NAPESHM_MXAG01_1 | E7: disturbance | F7: 43286 | J7: furrow shaper, torpedo | K7: 2.2
B8: =IF(ISNUMBER(MATCH(C8, Mgt_Unit!$C$5:$C$1018, 0)), INDEX(Mgt_Unit!$B$5:$B$1018, MATCH(C8, Mgt_Unit!$C$5:$C$1018, 0)), "") -> jennifer.moore | C8: NAPESHM_MXAG01_1 | E8: disturbance | F8: 43402 | J8: disc harrow | K8: 39
B9: =IF(ISNUMBER(MATCH(C9, Mgt_Unit!$C$5:$C$1018, 0)), INDEX(Mgt_Unit!$B$5:$B$1018, MATCH(C9, Mgt_Unit!$C$5:$C$1018, 0)), "") -> jennifer.moore | C9: NAPESHM_MXAG01_1 | E9: disturbance | F9: 43402 | J9: furrow shaper, torpedo | K9: 2.2
B10: =IF(ISNUMBER(MATCH(C10, Mgt_Unit!$C$5:$C$1018, 0)), INDEX(Mgt_Unit!$B$5:$B$1018, MATCH(C10, Mgt_Unit!$C$5:$C$1018, 0)), "") -> jennifer.moore | C10: NAPESHM_MXAG01_1 | E10: disturbance | F10: 43404 | J10: drill or airseeder, double disk | K10: 6.3
B11: =IF(ISNUMBER(MATCH(C11, Mgt_Unit!$C$5:$C$1018, 0)), INDEX(Mgt_Unit!$B$5:$B$1018, MATCH(C11, Mgt_Unit!$C$5:$C$1018, 0)), "") -> jennifer.moore | C11: NAPESHM_MXAG01_2 | E11: disturbance | F11: 43242 | J11: disc harrow | K11: 39
B12: =IF(ISNUMBER(MATCH(C12, Mgt_Unit!$C$5:$C$1018, 0)), INDEX(Mgt_Unit!$B$5:$B$1018, MATCH(C12, Mgt_Unit!$C$5:$C$1018, 0)), "") -> jennifer.moore | C12: NAPESHM_MXAG01_2 | E12: disturbance | F12: 43244 | J12: planter, double disk opnr | K12: 2.4
B13: =IF(ISNUMBER(MATCH(C13, Mgt_Unit!$C$5:$C$1018, 0)), INDEX(Mgt_Unit!$B$5:$B$1018, MATCH(C13, Mgt_Unit!$C$5:$C$1018, 0)), "") -> jennifer.moore | C13: NAPESHM_MXAG01_2 | E13: disturbance | F13: 43286 | J13: furrow shaper, torpedo | K13: 2.2
B14: =IF(ISNUMBER(MATCH(C14, Mgt_Unit!$C$5:$C$1018, 0)), INDEX(Mgt_Unit!$B$5:$B$1018, MATCH(C14, Mgt_Unit!$C$5:$C$1018, 0)), "") -> jennifer.moore | C14: NAPESHM_MXAG01_2 | E14: disturbance | F14: 43402 | J14: disc harrow | K14: 39
B15: =IF(ISNUMBER(MATCH(C15, Mgt_Unit!$C$5:$C$1018, 0)), INDEX(Mgt_Unit!$B$5:$B$1018, MATCH(C15, Mgt_Unit!$C$5:$C$1018, 0)), "") -> jennifer.moore | C15: NAPESHM_MXAG01_2 | E15: disturbance | F15: 43402 | J15: furrow shaper, torpedo | K15: 2.2
B16: =IF(ISNUMBER(MATCH(C16, Mgt_Unit!$C$5:$C$1018, 0)), INDEX(Mgt_Unit!$B$5:$B$1018, MATCH(C16, Mgt_Unit!$C$5:$C$1018, 0)), "") -> jennifer.moore | C16: NAPESHM_MXAG01_2 | E16: disturbance | F16: 43404 | J16: drill or airseeder, double disk | K16: 6.3
... B3297: =IF(ISNUMBER(MATCH(C3297, Mgt_Unit!$C$5:$C$1018, 0)), INDEX(Mgt_Unit!$B$5:$B$1018, MATCH(C3297, Mgt_Unit!$C$5:$C$1018, 0)), "") -> jennifer.moore | C3297: NAPESHM_USWI01_497 | E3297: disturbance | F3297: 43326 | J3297: cultipacker, roller | K3297: 36

Sheet Soil_Amendments
A1: Description | B1: Name of User | C1: SQL Database | D1: Unique Mgt & Crop Combo | E1: Unique Identifier | F1: Amendment Category | G1: Amendment Source | H1: Amend Date | I1: Amendment Rate | J1: Amendment Units | K1: Nitrogen added | L1: P2O5 added | M1: K2O added | N1: Water in Organic Amendment | O1: C/N ratio of Organic Amendment | P1: User may add any notes here
A2: Type | B2: <autofill> | C2: <auto-generated> | D2: <dropdown> | E2: <autofill> | F2: <dropdown> | G2: <dropdown> | H2: <date> | I2: <numeric> | J2: <character> | K2: <numeric> | L2: <numeric> | M2: <numeric> | N2: <numeric> | O2: <numeric> | P2: <character>
A3: Units | B3: NA | C3: NA | D3: NA | E3: NA | F3: NA | G3: NA | H3: MM/DD/YYYY | I3: <user-defined> | J3: <user-defined> | K3: <see Column J> | L3: <see Column J> | M3: <see Column J> | N3: % | O3: ratio
B4: user_name | C4: MGT_id | D4: MGT_combo | E4: SA_id | F4: SA_cat | G4: SA_source | H4: SA_date | I4: SA_rate | J4: SA_units | K4: SA_N | L4: SA_P2O5 | M4: SA_K2O | N4: SA_H2O_per | O4: SA_CN | P4: SA_notes
B5: =IF(ISNUMBER(MATCH(D5, Mgt_Unit!$C$5:$C$1018, 0)), INDEX(Mgt_Unit!$B$5:$B$1018, MATCH(D5, Mgt_Unit!$C$5:$C$1018, 0)), "") -> jennifer.moore | D5: NAPESHM_MXPU01_70 | F5: Organic | G5: cattle manure (0.35-0.20-0.35) | H5: 43280 | I5: 1500 | J5: kg ha-1
B6: =IF(ISNUMBER(MATCH(D6, Mgt_Unit!$C$5:$C$1018, 0)), INDEX(Mgt_Unit!$B$5:$B$1018, MATCH(D6, Mgt_Unit!$C$5:$C$1018, 0)), "") -> jennifer.moore | D6: NAPESHM_MXPU01_71 | F6: Organic | G6: cattle manure (0.35-0.20-0.35) | H6: 43280 | I6: 1500 | J6: kg ha-1
B7: =IF(ISNUMBER(MATCH(D7, Mgt_Unit!$C$5:$C$1018, 0)), INDEX(Mgt_Unit!$B$5:$B$1018, MATCH(D7, Mgt_Unit!$C$5:$C$1018, 0)), "") -> jennifer.moore | D7: NAPESHM_MXPU01_72 | F7: Organic | G7: cattle manure (0.35-0.20-0.35) | H7: 43280 | I7: 1500 | J7: kg ha-1
B8: =IF(ISNUMBER(MATCH(D8, Mgt_Unit!$C$5:$C$1018, 0)), INDEX(Mgt_Unit!$B$5:$B$1018, MATCH(D8, Mgt_Unit!$C$5:$C$1018, 0)), "") -> jennifer.moore | D8: NAPESHM_MXPU01_72 | F8: Organic | G8: cattle manure (0.35-0.20-0.35) | H8: 43645 | I8: 1500 | J8: kg ha-1
B9: =IF(ISNUMBER(MATCH(D9, Mgt_Unit!$C$5:$C$1018, 0)), INDEX(Mgt_Unit!$B$5:$B$1018, MATCH(D9, Mgt_Unit!$C$5:$C$1018, 0)), "") -> jennifer.moore | D9: NAPESHM_MXPU01_73 | F9: Organic | G9: cattle manure (0.35-0.20-0.35) | H9: 43280 | I9: 1500 | J9: kg ha-1
B10: =IF(ISNUMBER(MATCH(D10, Mgt_Unit!$C$5:$C$1018, 0)), INDEX(Mgt_Unit!$B$5:$B$1018, MATCH(D10, Mgt_Unit!$C$5:$C$1018, 0)), "") -> jennifer.moore | D10: NAPESHM_MXPU01_73 | F10: Organic | G10: cattle manure (0.35-0.20-0.35) | H10: 43645 | I10: 1500 | J10: kg ha-1
B11: =IF(ISNUMBER(MATCH(D11, Mgt_Unit!$C$5:$C$1018, 0)), INDEX(Mgt_Unit!$B$5:$B$1018, MATCH(D11, Mgt_Unit!$C$5:$C$1018, 0)), "") -> jennifer.moore | D11: NAPESHM_MXPU01_74 | F11: Organic | G11: cattle manure (0.35-0.20-0.35) | H11: 43280 | I11: 1500 | J11: kg ha-1
B12: =IF(ISNUMBER(MATCH(D12, Mgt_Unit!$C$5:$C$1018, 0)), INDEX(Mgt_Unit!$B$5:$B$1018, MATCH(D12, Mgt_Unit!$C$5:$C$1018, 0)), "") -> jennifer.moore | D12: NAPESHM_MXPU01_75 | F12: Organic | G12: cattle manure (0.35-0.20-0.35) | H12: 43280 | I12: 1500 | J12: kg ha-1
B13: =IF(ISNUMBER(MATCH(D13, Mgt_Unit!$C$5:$C$1018, 0)), INDEX(Mgt_Unit!$B$5:$B$1018, MATCH(D13, Mgt_Unit!$C$5:$C$1018, 0)), "") -> jennifer.moore | D13: NAPESHM_MXPU01_75 | F13: Organic | G13: cattle manure (0.35-0.20-0.35) | H13: 43645 | I13: 1500 | J13: kg ha-1
B14: =IF(ISNUMBER(MATCH(D14, Mgt_Unit!$C$5:$C$1018, 0)), INDEX(Mgt_Unit!$B$5:$B$1018, MATCH(D14, Mgt_Unit!$C$5:$C$1018, 0)), "") -> jennifer.moore | D14: NAPESHM_MXPU01_76 | F14: Organic | G14: cattle manure (0.35-0.20-0.35) | H14: 43280 | I14: 1500 | J14: kg ha-1
B15: =IF(ISNUMBER(MATCH(D15, Mgt_Unit!$C$5:$C$1018, 0)), INDEX(Mgt_Unit!$B$5:$B$1018, MATCH(D15, Mgt_Unit!$C$5:$C$1018, 0)), "") -> jennifer.moore | D15: NAPESHM_MXPU01_76 | F15: Organic | G15: cattle manure (0.35-0.20-0.35) | H15: 43645 | I15: 1500 | J15: kg ha-1
B16: =IF(ISNUMBER(MATCH(D16, Mgt_Unit!$C$5:$C$1018, 0)), INDEX(Mgt_Unit!$B$5:$B$1018, MATCH(D16, Mgt_Unit!$C$5:$C$1018, 0)), "") -> jennifer.moore | D16: NAPESHM_USAL01_139 | F16: Organic | G16: poultry litter | H16: 43146 | I16: 72 | J16: lbs acre-1 N
... B112: =IF(ISNUMBER(MATCH(D112, Mgt_Unit!$C$5:$C$1018, 0)), INDEX(Mgt_Unit!$B$5:$B$1018, MATCH(D112, Mgt_Unit!$C$5:$C$1018, 0)), "") -> jennifer.moore | D112: NAPESHM_USWV01_503 | F112: Organic | G112: cattle manure | H112: 43556 | I112: 31800 | J112: kg ha-1
B113: =IF(ISNUMBER(MATCH(D113, Mgt_Unit!$C$5:$C$1018, 0)), INDEX(Mgt_Unit!$B$5:$B$1018, MATCH(D113, Mgt_Unit!$C$5:$C$1018, 0)), "")
B114: =IF(ISNUMBER(MATCH(D114, Mgt_Unit!$C$5:$C$1018, 0)), INDEX(Mgt_Unit!$B$5:$B$1018, MATCH(D114, Mgt_Unit!$C$5:$C$1018, 0)), "")
B115: =IF(ISNUMBER(MATCH(D115, Mgt_Unit!$C$5:$C$1018, 0)), INDEX(Mgt_Unit!$B$5:$B$1018, MATCH(D115, Mgt_Unit!$C$5:$C$1018, 0)), "")
B116: =IF(ISNUMBER(MATCH(D116, Mgt_Unit!$C$5:$C$1018, 0)), INDEX(Mgt_Unit!$B$5:$B$1018, MATCH(D116, Mgt_Unit!$C$5:$C$1018, 0)), "")
B117: =IF(ISNUMBER(MATCH(D117, Mgt_Unit!$C$5:$C$1018, 0)), INDEX(Mgt_Unit!$B$5:$B$1018, MATCH(D117, Mgt_Unit!$C$5:$C$1018, 0)), "")
B118: =IF(ISNUMBER(MATCH(D118, Mgt_Unit!$C$5:$C$1018, 0)), INDEX(Mgt_Unit!$B$5:$B$1018, MATCH(D118, Mgt_Unit!$C$5:$C$1018, 0)), "")
B119: =IF(ISNUMBER(MATCH(D119, Mgt_Unit!$C$5:$C$1018, 0)), INDEX(Mgt_Unit!$B$5:$B$1018, MATCH(D119, Mgt_Unit!$C$5:$C$1018, 0)), "")
B120: =IF(ISNUMBER(MATCH(D120, Mgt_Unit!$C$5:$C$1018, 0)), INDEX(Mgt_Unit!$B$5:$B$1018, MATCH(D120, Mgt_Unit!$C$5:$C$1018, 0)), "")
B121: =IF(ISNUMBER(MATCH(D121, Mgt_Unit!$C$5:$C$1018, 0)), INDEX(Mgt_Unit!$B$5:$B$1018, MATCH(D121, Mgt_Unit!$C$5:$C$1018, 0)), "")
B122: =IF(ISNUMBER(MATCH(D122, Mgt_Unit!$C$5:$C$1018, 0)), INDEX(Mgt_Unit!$B$5:$B$1018, MATCH(D122, Mgt_Unit!$C$5:$C$1018, 0)), "")
B123: =IF(ISNUMBER(MATCH(D123, Mgt_Unit!$C$5:$C$1018, 0)), INDEX(Mgt_Unit!$B$5:$B$1018, MATCH(D123, Mgt_Unit!$C$5:$C$1018, 0)), "")
B124: =IF(ISNUMBER(MATCH(D124, Mgt_Unit!$C$5:$C$1018, 0)), INDEX(Mgt_Unit!$B$5:$B$1018, MATCH(D124, Mgt_Unit!$C$5:$C$1018, 0)), "")
... B1003: =IF(ISNUMBER(MATCH(D1003, Mgt_Unit!$C$5:$C$1018, 0)), INDEX(Mgt_Unit!$B$5:$B$1018, MATCH(D1003, Mgt_Unit!$C$5:$C$1018, 0)), "")

Sheet Animal_Diversity
A1: Description | B1: Name of User | C1: SQL Database | D1: Unique Mgt & Crop Combo | E1: Unique Identifier | F1: Animal Type | G1: Grazing intensity | H1: Animal Count | I1: Animal Start Date | J1: Animal End Date | K1: Animal Unit Months | L1: User may add any notes here
A2: Type | B2: <autofill> | C2: <auto-generated> | D2: <dropdown> | E2: <autofill> | F2: <dropdown> | G2: <dropdown> | H2: <numeric> | I2: <date> | J2: <date> | K2: <numeric> | L2: <character>
A3: Units | B3: NA | C3: NA | D3: NA | E3: NA | F3: NA | G3: NA | H3: head / acre | I3: MM/DD/YYYY | J3: MM/DD/YYYY | K3: NA | L3: NA
B4: user_name | C4: MGT_id | D4: MGT_combo | E4: AD_id | F4: AD_type | G4: AD_intensity | H4: AD_count | I4: AD_start_date | J4: AD_end_date | K4: AD_aum | L4: AD_notes
B5: =IF(ISNUMBER(MATCH(D5, Mgt_Unit!$C$5:$C$1018, 0)), INDEX(Mgt_Unit!$B$5:$B$1018, MATCH(D5, Mgt_Unit!$C$5:$C$1018, 0)), "") -> jennifer.moore | D5: NAPESHM_USAL04_161 | F5: cattle | G5: Medium | H5: 1.2 | I5: 42399 | J5: 42461 | L5: cattle ha-1
B6: =IF(ISNUMBER(MATCH(D6, Mgt_Unit!$C$5:$C$1018, 0)), INDEX(Mgt_Unit!$B$5:$B$1018, MATCH(D6, Mgt_Unit!$C$5:$C$1018, 0)), "") -> jennifer.moore | D6: NAPESHM_USAL04_161 | F6: cattle | G6: Medium | H6: 1.2 | I6: 42765 | J6: 42826 | L6: cattle ha-1
B7: =IF(ISNUMBER(MATCH(D7, Mgt_Unit!$C$5:$C$1018, 0)), INDEX(Mgt_Unit!$B$5:$B$1018, MATCH(D7, Mgt_Unit!$C$5:$C$1018, 0)), "") -> jennifer.moore | D7: NAPESHM_USAL04_161 | F7: cattle | G7: Medium | H7: 2.5 | I7: 42998 | J7: 43084 | L7: cattle ha-1
B8: =IF(ISNUMBER(MATCH(D8, Mgt_Unit!$C$5:$C$1018, 0)), INDEX(Mgt_Unit!$B$5:$B$1018, MATCH(D8, Mgt_Unit!$C$5:$C$1018, 0)), "") -> jennifer.moore | D8: NAPESHM_USAL04_161 | F8: cattle | G8: Medium | H8: 2.5 | I8: 43235 | J8: 43374 | L8: cattle ha-1
B9: =IF(ISNUMBER(MATCH(D9, Mgt_Unit!$C$5:$C$1018, 0)), INDEX(Mgt_Unit!$B$5:$B$1018, MATCH(D9, Mgt_Unit!$C$5:$C$1018, 0)), "") -> jennifer.moore | D9: NAPESHM_USAL04_161 | F9: cattle | G9: Medium | H9: 1.2 | I9: 43495 | J9: 43556 | L9: cattle ha-1
B10: =IF(ISNUMBER(MATCH(D10, Mgt_Unit!$C$5:$C$1018, 0)), INDEX(Mgt_Unit!$B$5:$B$1018, MATCH(D10, Mgt_Unit!$C$5:$C$1018, 0)), "") -> jennifer.moore | D10: NAPESHM_USAR01_165 | F10: animal | G10: Heavy | I10: 43466 | J10: 43830
B11: =IF(ISNUMBER(MATCH(D11, Mgt_Unit!$C$5:$C$1018, 0)), INDEX(Mgt_Unit!$B$5:$B$1018, MATCH(D11, Mgt_Unit!$C$5:$C$1018, 0)), "") -> jennifer.moore | D11: NAPESHM_USAR01_166 | F11: animal | G11: Medium | I11: 43570 | J11: 43586
B12: =IF(ISNUMBER(MATCH(D12, Mgt_Unit!$C$5:$C$1018, 0)), INDEX(Mgt_Unit!$B$5:$B$1018, MATCH(D12, Mgt_Unit!$C$5:$C$1018, 0)), "") -> jennifer.moore | D12: NAPESHM_USAR01_166 | F12: animal | G12: Medium | I12: 43615 | J12: 43629
B13: =IF(ISNUMBER(MATCH(D13, Mgt_Unit!$C$5:$C$1018, 0)), INDEX(Mgt_Unit!$B$5:$B$1018, MATCH(D13, Mgt_Unit!$C$5:$C$1018, 0)), "") -> jennifer.moore | D13: NAPESHM_USAR01_166 | F13: animal | G13: Medium | I13: 43668 | J13: 43679
B14: =IF(ISNUMBER(MATCH(D14, Mgt_Unit!$C$5:$C$1018, 0)), INDEX(Mgt_Unit!$B$5:$B$1018, MATCH(D14, Mgt_Unit!$C$5:$C$1018, 0)), "") -> jennifer.moore | D14: NAPESHM_USAR01_166 | F14: animal | G14: Medium | I14: 43720 | J14: 43727
B15: =IF(ISNUMBER(MATCH(D15, Mgt_Unit!$C$5:$C$1018, 0)), INDEX(Mgt_Unit!$B$5:$B$1018, MATCH(D15, Mgt_Unit!$C$5:$C$1018, 0)), "") -> jennifer.moore | D15: NAPESHM_USAZ01_167 | F15: cattle | G15: Light | H15: 0.23287671 | I15: 41884 | J15: 41897 | L15: cattle ac-1
B16: =IF(ISNUMBER(MATCH(D16, Mgt_Unit!$C$5:$C$1018, 0)), INDEX(Mgt_Unit!$B$5:$B$1018, MATCH(D16, Mgt_Unit!$C$5:$C$1018, 0)), "") -> jennifer.moore | D16: NAPESHM_USAZ01_167 | F16: cattle | G16: Light | H16: 0.23287671 | I16: 42227 | J16: 42236 | L16: cattle ac-1
B17: =IF(ISNUMBER(MATCH(D17, Mgt_Unit!$C$5:$C$1018, 0)), INDEX(Mgt_Unit!$B$5:$B$1018, MATCH(D17, Mgt_Unit!$C$5:$C$1018, 0)), "") -> jennifer.moore | D17: NAPESHM_USAZ01_167 | F17: cattle | G17: Light | H17: 0.23287671 | I17: 42604 | J17: 42635 | L17: cattle ac-1
B18: =IF(ISNUMBER(MATCH(D18, Mgt_Unit!$C$5:$C$1018, 0)), INDEX(Mgt_Unit!$B$5:$B$1018, MATCH(D18, Mgt_Unit!$C$5:$C$1018, 0)), "") -> jennifer.moore | D18: NAPESHM_USAZ01_167 | F18: cattle | G18: Light | H18: 0.23287671 | I18: 42955 | J18: 42959 | L18: cattle ac-1
B19: =IF(ISNUMBER(MATCH(D19, Mgt_Unit!$C$5:$C$1018, 0)), INDEX(Mgt_Unit!$B$5:$B$1018, MATCH(D19, Mgt_Unit!$C$5:$C$1018, 0)), "") -> jennifer.moore | D19: NAPESHM_USAZ01_167 | F19: cattle | G19: Light | H19: 0.23287671 | I19: 43277 | J19: 43296 | L19: cattle ac-1
B20: =IF(ISNUMBER(MATCH(D20, Mgt_Unit!$C$5:$C$1018, 0)), INDEX(Mgt_Unit!$B$5:$B$1018, MATCH(D20, Mgt_Unit!$C$5:$C$1018, 0)), "") -> jennifer.moore | D20: NAPESHM_USAZ01_167 | F20: cattle | G20: Light | H20: 0.23287671 | I20: 43657 | J20: 43676 | L20: cattle ac-1
B21: =IF(ISNUMBER(MATCH(D21, Mgt_Unit!$C$5:$C$1018, 0)), INDEX(Mgt_Unit!$B$5:$B$1018, MATCH(D21, Mgt_Unit!$C$5:$C$1018, 0)), "") -> jennifer.moore | D21: NAPESHM_USAZ01_168 | F21: cattle | G21: Light | H21: 0.10250818 | I21: 41569 | J21: 41578 | L21: cattle ac-1
B22: =IF(ISNUMBER(MATCH(D22, Mgt_Unit!$C$5:$C$1018, 0)), INDEX(Mgt_Unit!$B$5:$B$1018, MATCH(D22, Mgt_Unit!$C$5:$C$1018, 0)), "") -> jennifer.moore | D22: NAPESHM_USAZ01_168 | F22: cattle | G22: Light | H22: 0.10250818 | I22: 41933 | J22: 41943 | L22: cattle ac-1
B23: =IF(ISNUMBER(MATCH(D23, Mgt_Unit!$C$5:$C$1018, 0)), INDEX(Mgt_Unit!$B$5:$B$1018, MATCH(D23, Mgt_Unit!$C$5:$C$1018, 0)), "") -> jennifer.moore | D23: NAPESHM_USAZ01_168 | F23: cattle | G23: Light | H23: 0.10250818 | I23: 42289 | J23: 42331 | L23: cattle ac-1
B24: =IF(ISNUMBER(MATCH(D24, Mgt_Unit!$C$5:$C$1018, 0)), INDEX(Mgt_Unit!$B$5:$B$1018, MATCH(D24, Mgt_Unit!$C$5:$C$1018, 0)), "") -> jennifer.moore | D24: NAPESHM_USAZ01_168 | F24: cattle | G24: Light | H24: 0.10250818 | I24: 42654 | J24: 42738 | L24: cattle ac-1
B25: =IF(ISNUMBER(MATCH(D25, Mgt_Unit!$C$5:$C$1018, 0)), INDEX(Mgt_Unit!$B$5:$B$1018, MATCH(D25, Mgt_Unit!$C$5:$C$1018, 0)), "") -> jennifer.moore | D25: NAPESHM_USAZ01_168 | F25: cattle | G25: Light | H25: 0.10250818 | I25: 43077 | J25: 43102 | L25: cattle ac-1
B26: =IF(ISNUMBER(MATCH(D26, Mgt_Unit!$C$5:$C$1018, 0)), INDEX(Mgt_Unit!$B$5:$B$1018, MATCH(D26, Mgt_Unit!$C$5:$C$1018, 0)), "") -> jennifer.moore | D26: NAPESHM_USAZ01_168 | F26: cattle | G26: Light | H26: 0.10250818 | I26: 43439 | J26: 43478 | L26: cattle ac-1
... B78: =IF(ISNUMBER(MATCH(D78, Mgt_Unit!$C$5:$C$1018, 0)), INDEX(Mgt_Unit!$B$5:$B$1018, MATCH(D78, Mgt_Unit!$C$5:$C$1018, 0)), "") -> jennifer.moore | D78: NAPESHM_USWV01_505 | F78: sheep | G78: Medium | H78: 132 | I78: 43800 | J78: 43830 | L78: 76-132 animals ha-1 day-1
B79: =IF(ISNUMBER(MATCH(D79, Mgt_Unit!$C$5:$C$1018, 0)), INDEX(Mgt_Unit!$B$5:$B$1018, MATCH(D79, Mgt_Unit!$C$5:$C$1018, 0)), "") -> jennifer.moore | D79: NAPESHM_USWY01_506 | F79: animal | G79: Heavy | I79: 41796 | J79: 41897
B80: =IF(ISNUMBER(MATCH(D80, Mgt_Unit!$C$5:$C$1018, 0)), INDEX(Mgt_Unit!$B$5:$B$1018, MATCH(D80, Mgt_Unit!$C$5:$C$1018, 0)), "") -> jennifer.moore | D80: NAPESHM_USWY01_506 | F80: animal | G80: Heavy | I80: 42157 | J80: 42271
B81: =IF(ISNUMBER(MATCH(D81, Mgt_Unit!$C$5:$C$1018, 0)), INDEX(Mgt_Unit!$B$5:$B$1018, MATCH(D81, Mgt_Unit!$C$5:$C$1018, 0)), "") -> jennifer.moore | D81: NAPESHM_USWY01_506 | F81: animal | G81: Heavy | I81: 42523 | J81: 42635
B82: =IF(ISNUMBER(MATCH(D82, Mgt_Unit!$C$5:$C$1018, 0)), INDEX(Mgt_Unit!$B$5:$B$1018, MATCH(D82, Mgt_Unit!$C$5:$C$1018, 0)), "") -> jennifer.moore | D82: NAPESHM_USWY01_506 | F82: animal | G82: Heavy | I82: 42887 | J82: 43004
B83: =IF(ISNUMBER(MATCH(D83, Mgt_Unit!$C$5:$C$1018, 0)), INDEX(Mgt_Unit!$B$5:$B$1018, MATCH(D83, Mgt_Unit!$C$5:$C$1018, 0)), "") -> jennifer.moore | D83: NAPESHM_USWY01_506 | F83: animal | G83: Heavy | I83: 43256 | J83: 43370
B84: =IF(ISNUMBER(MATCH(D84, Mgt_Unit!$C$5:$C$1018, 0)), INDEX(Mgt_Unit!$B$5:$B$1018, MATCH(D84, Mgt_Unit!$C$5:$C$1018, 0)), "") -> jennifer.moore | D84: NAPESHM_USWY01_507 | F84: animal | G84: Light | I84: 41796 | J84: 41897
B85: =IF(ISNUMBER(MATCH(D85, Mgt_Unit!$C$5:$C$1018, 0)), INDEX(Mgt_Unit!$B$5:$B$1018, MATCH(D85, Mgt_Unit!$C$5:$C$1018, 0)), "") -> jennifer.moore | D85: NAPESHM_USWY01_507 | F85: animal | G85: Light | I85: 42157 | J85: 42271
B86: =IF(ISNUMBER(MATCH(D86, Mgt_Unit!$C$5:$C$1018, 0)), INDEX(Mgt_Unit!$B$5:$B$1018, MATCH(D86, Mgt_Unit!$C$5:$C$1018, 0)), "") -> jennifer.moore | D86: NAPESHM_USWY01_507 | F86: animal | G86: Light | I86: 42523 | J86: 42635
B87: =IF(ISNUMBER(MATCH(D87, Mgt_Unit!$C$5:$C$1018, 0)), INDEX(Mgt_Unit!$B$5:$B$1018, MATCH(D87, Mgt_Unit!$C$5:$C$1018, 0)), "") -> jennifer.moore | D87: NAPESHM_USWY01_507 | F87: animal | G87: Light | I87: 42887 | J87: 43004
B88: =IF(ISNUMBER(MATCH(D88, Mgt_Unit!$C$5:$C$1018, 0)), INDEX(Mgt_Unit!$B$5:$B$1018, MATCH(D88, Mgt_Unit!$C$5:$C$1018, 0)), "") -> jennifer.moore | D88: NAPESHM_USWY01_507 | F88: animal | G88: Light | I88: 43256 | J88: 43370
B89: =IF(ISNUMBER(MATCH(D89, Mgt_Unit!$C$5:$C$1018, 0)), INDEX(Mgt_Unit!$B$5:$B$1018, MATCH(D89, Mgt_Unit!$C$5:$C$1018, 0)), "") -> jennifer.moore | D89: NAPESHM_USNC03_362 | F89: cattle | G89: Medium | I89: 42877 | J89: 42884
B90: =IF(ISNUMBER(MATCH(D90, Mgt_Unit!$C$5:$C$1018, 0)), INDEX(Mgt_Unit!$B$5:$B$1018, MATCH(D90, Mgt_Unit!$C$5:$C$1018, 0)), "") -> jennifer.moore | D90: NAPESHM_USNC03_362 | F90: cattle | G90: Medium | I90: 42997 | J90: 43004
... B128: =IF(ISNUMBER(MATCH(D128, Mgt_Unit!$C$5:$C$1018, 0)), INDEX(Mgt_Unit!$B$5:$B$1018, MATCH(D128, Mgt_Unit!$C$5:$C$1018, 0)), "") -> jennifer.moore | D128: NAPESHM_USOK01_432 | F128: cattle | G128: Medium | I128: 41844 | J128: 43830
...

Sheet Soil_Test
A1: Description | B1: Name of User | C1: SQL Database | D1: Unique Mgt ID | E1: Unique Identifier | F1: Soil Testing Laboratory | G1: Soil Sample Date | H1: Soil Test Depth | I1: Soil Organic Matter | J1: Soil pH | K1: Soil Electrical Conductivity | L1: Add any notes here
A2: Type | B2: <autofill> | C2: <auto-generated> | D2: <dropdown> | E2: <autofill> | F2: <character> | G2: <character> | H2: <numeric> | I2: <numeric> | J2: <numeric> | K2: <numeric> | L2: <character>
A3: Units | B3: NA | C3: NA | D3: NA | E3: NA | F3: NA | G3: MM/DD/YYYY | H3: inches | I3: % | J3: % | K3: dS/m | L3: NA
B4: user_name | C4: MGT_id | D4: MGT_combo | E4: ST_id | F4: ST_test_lab | G4: ST_test_date | H4: ST_test_depth | I4: ST_OM | J4: ST_pH | K4: ST_EC | L4: ST_notes
B5: =IF(ISNUMBER(MATCH(D5, Mgt_Unit!$C$5:$C$1018, 0)), INDEX(Mgt_Unit!$B$5:$B$1018, MATCH(D5, Mgt_Unit!$C$5:$C$1018, 0)), "") -> jennifer.moore | D5: NAPESHM_MXAG01_1 | F5: SHI | I5: 2.8 | J5: 7 | K5: 0.69
B6: =IF(ISNUMBER(MATCH(D6, Mgt_Unit!$C$5:$C$1018, 0)), INDEX(Mgt_Unit!$B$5:$B$1018, MATCH(D6, Mgt_Unit!$C$5:$C$1018, 0)), "") -> jennifer.moore | D6: NAPESHM_MXAG01_2 | F6: SHI | I6: 3 | J6: 7.53 | K6: 0.37
B7: =IF(ISNUMBER(MATCH(D7, Mgt_Unit!$C$5:$C$1018, 0)), INDEX(Mgt_Unit!$B$5:$B$1018, MATCH(D7, Mgt_Unit!$C$5:$C$1018, 0)), "") -> jennifer.moore | D7: NAPESHM_MXAG01_3 | F7: SHI | I7: 2.6 | J7: 7.54 | K7: 0.533
B8: =IF(ISNUMBER(MATCH(D8, Mgt_Unit!$C$5:$C$1018, 0)), INDEX(Mgt_Unit!$B$5:$B$1018, MATCH(D8, Mgt_Unit!$C$5:$C$1018, 0)), "") -> jennifer.moore | D8: NAPESHM_MXAG01_4 | F8: SHI | I8: 2 | J8: 7.89 | K8: 0.741
B9: =IF(ISNUMBER(MATCH(D9, Mgt_Unit!$C$5:$C$1018, 0)), INDEX(Mgt_Unit!$B$5:$B$1018, MATCH(D9, Mgt_Unit!$C$5:$C$1018, 0)), "") -> jennifer.moore | D9: NAPESHM_MXAG01_5 | F9: SHI | I9: 2.8 | J9: 7.69 | K9: 0.645
B10: =IF(ISNUMBER(MATCH(D10, Mgt_Unit!$C$5:$C$1018, 0)), INDEX(Mgt_Unit!$B$5:$B$1018, MATCH(D10, Mgt_Unit!$C$5:$C$1018, 0)), "") -> jennifer.moore | D10: NAPESHM_MXAG01_1 | F10: SHI | I10: 2.8 | J10: 6.52 | K10: 0.539
B11: =IF(ISNUMBER(MATCH(D11, Mgt_Unit!$C$5:$C$1018, 0)), INDEX(Mgt_Unit!$B$5:$B$1018, MATCH(D11, Mgt_Unit!$C$5:$C$1018, 0)), "") -> jennifer.moore | D11: NAPESHM_MXAG01_2 | F11: SHI | I11: 2.7 | J11: 6.74 | K11: 0.405
B12: =IF(ISNUMBER(MATCH(D12, Mgt_Unit!$C$5:$C$1018, 0)), INDEX(Mgt_Unit!$B$5:$B$1018, MATCH(D12, Mgt_Unit!$C$5:$C$1018, 0)), "") -> jennifer.moore | D12: NAPESHM_MXAG01_3 | F12: SHI | I12: 2.3 | J12: 7.06 | K12: 0.506
B13: =IF(ISNUMBER(MATCH(D13, Mgt_Unit!$C$5:$C$1018, 0)), INDEX(Mgt_Unit!$B$5:$B$1018, MATCH(D13, Mgt_Unit!$C$5:$C$1018, 0)), "") -> jennifer.moore | D13: NAPESHM_MXAG01_4 | F13: SHI | I13: 2.4 | J13: 6.95 | K13: 0.548
B14: =IF(ISNUMBER(MATCH(D14, Mgt_Unit!$C$5:$C$1018, 0)), INDEX(Mgt_Unit!$B$5:$B$1018, MATCH(D14, Mgt_Unit!$C$5:$C$1018, 0)), "") -> jennifer.moore | D14: NAPESHM_MXAG01_5 | F14: SHI | I14: 2.4 | J14: 8.14 | K14: 0.545
B15: =IF(ISNUMBER(MATCH(D15, Mgt_Unit!$C$5:$C$1018, 0)), INDEX(Mgt_Unit!$B$5:$B$1018, MATCH(D15, Mgt_Unit!$C$5:$C$1018, 0)), "") -> jennifer.moore | D15: NAPESHM_MXEM01_6 | F15: SHI | I15: 4.3 | J15: 5.56 | K15: 0.127
B16: =IF(ISNUMBER(MATCH(D16, Mgt_Unit!$C$5:$C$1018, 0)), INDEX(Mgt_Unit!$B$5:$B$1018, MATCH(D16, Mgt_Unit!$C$5:$C$1018, 0)), "") -> jennifer.moore | D16: NAPESHM_MXEM01_15 | F16: SHI | I16: 3.9 | J16: 5.57 | K16: 0.123
... B153: =IF(ISNUMBER(MATCH(D153, Mgt_Unit!$C$5:$C$1018, 0)), INDEX(Mgt_Unit!$B$5:$B$1018, MATCH(D153, Mgt_Unit!$C$5:$C$1018, 0)), "") -> jennifer.moore | D153: NAPESHM_MXQT01_77 | F153: SHI | I153: 2.7 | J153: 7.34 | K153: 0.367
B154: =IF(ISNUMBER(MATCH(D154, Mgt_Unit!$C$5:$C$1018, 0)), INDEX(Mgt_Unit!$B$5:$B$1018, MATCH(D154, Mgt_Unit!$C$5:$C$1018, 0)), "") -> jennifer.moore | D154: NAPESHM_MXQT01_78 | F154: SHI | I154: 3
B155: =IF(ISNUMBER(MATCH(D155, Mgt_Unit!$C$5:$C$1018, 0)), INDEX(Mgt_Unit!$B$5:$B$1018, MATCH(D155, Mgt_Unit!$C$5:$C$1018, 0)), "") -> jennifer.moore | D155: NAPESHM_MXQT01_79 | F155: SHI | I155: 3.2 | J155: 7.16 | K155: 0.304
B156: =IF(ISNUMBER(MATCH(D156, Mgt_Unit!$C$5:$C$1018, 0)), INDEX(Mgt_Unit!$B$5:$B$1018, MATCH(D156, Mgt_Unit!$C$5:$C$1018, 0)), "") -> jennifer.moore | D156: NAPESHM_MXQT01_80 | F156: SHI | I156: 3.5 | J156: 7.33 | K156: 0.246
B157: =IF(ISNUMBER(MATCH(D157, Mgt_Unit!$C$5:$C$1018, 0)), INDEX(Mgt_Unit!$B$5:$B$1018, MATCH(D157, Mgt_Unit!$C$5:$C$1018, 0)), "") -> jennifer.moore | D157: NAPESHM_MXQT01_81 | F157: SHI | I157: 3.1 | J157: 7.29 | K157: 0.263
B158: =IF(ISNUMBER(MATCH(D158, Mgt_Unit!$C$5:$C$1018, 0)), INDEX(Mgt_Unit!$B$5:$B$1018, MATCH(D158, Mgt_Unit!$C$5:$C$1018, 0)), "") -> jennifer.moore | D158: NAPESHM_MXQT01_82 | F158: SHI | I158: 3.4 | J158: 7.3 | K158: 0.308
B159: =IF(ISNUMBER(MATCH(D159, Mgt_Unit!$C$5:$C$1018, 0)), INDEX(Mgt_Unit!$B$5:$B$1018, MATCH(D159, Mgt_Unit!$C$5:$C$1018, 0)), "") -> jennifer.moore | D159: NAPESHM_MXQT01_77 | F159: SHI | I159: 2.9 | J159: 7.35 | K159: 0.271
B160: =IF(ISNUMBER(MATCH(D160, Mgt_Unit!$C$5:$C$1018, 0)), INDEX(Mgt_Unit!$B$5:$B$1018, MATCH(D160, Mgt_Unit!$C$5:$C$1018, 0)), "") -> jennifer.moore | D160: NAPESHM_MXQT01_78 | F160: SHI | I160: 3.1 | J160: 7.48 | K160: 0.21
B161: =IF(ISNUMBER(MATCH(D161, Mgt_Unit!$C$5:$C$1018, 0)), INDEX(Mgt_Unit!$B$5:$B$1018, MATCH(D161, Mgt_Unit!$C$5:$C$1018, 0)), "") -> jennifer.moore | D161: NAPESHM_MXQT01_79 | F161: SHI | I161: 3.2 | J161: 7.42 | K161: 0.288
B162: =IF(ISNUMBER(MATCH(D162, Mgt_Unit!$C$5:$C$1018, 0)), INDEX(Mgt_Unit!$B$5:$B$1018, MATCH(D162, Mgt_Unit!$C$5:$C$1018, 0)), "") -> jennifer.moore | D162: NAPESHM_MXQT01_80 | F162: SHI | I162: 3.5 | J162: 7.31 | K162: 0.252
B163: =IF(ISNUMBER(MATCH(D163, Mgt_Unit!$C$5:$C$1018, 0)), INDEX(Mgt_Unit!$B$5:$B$1018, MATCH(D163, Mgt_Unit!$C$5:$C$1018, 0)), "") -> jennifer.moore | D163: NAPESHM_MXQT01_81 | F163: SHI | I163: 2.6 | J163: 7.59 | K163: 0.249
B164: =IF(ISNUMBER(MATCH(D164, Mgt_Unit!$C$5:$C$1018, 0)), INDEX(Mgt_Unit!$B$5:$B$1018, MATCH(D164, Mgt_Unit!$C$5:$C$1018, 0)), "") -> jennifer.moore | D164: NAPESHM_MXQT01_82 | F164: SHI | I164: 2.8 | J164: 7.55 | K164: 0.233
B165: =IF(ISNUMBER(MATCH(D165, Mgt_Unit!$C$5:$C$1018, 0)), INDEX(Mgt_Unit!$B$5:$B$1018, MATCH(D165, Mgt_Unit!$C$5:$C$1018, 0)), "") -> jennifer.moore | D165: NAPESHM_MXQT02_83 | F165: SHI | I165: 4.4 | J165: 5.55 | K165: 0.408
B166: =IF(ISNUMBER(MATCH(D166, Mgt_Unit!$C$5:$C$1018, 0)), INDEX(Mgt_Unit!$B$5:$B$1018, MATCH(D166, Mgt_Unit!$C$5:$C$1018, 0)), "") -> jennifer.moore | D166: NAPESHM_MXQT02_85 | F166: SHI | I166: 3.1 | J166: 5.58 | K166: 0.196
... B198: =IF(ISNUMBER(MATCH(D198, Mgt_Unit!$C$5:$C$1018, 0)), INDEX(Mgt_Unit!$B$5:$B$1018, MATCH(D198, Mgt_Unit!$C$5:$C$1018, 0)), "") -> jennifer.moore | D198: NAPESHM_MXSL01_99 | F198: SHI | I198: 4.1 | J198: 7.68 | K198: 0.427
B199: =IF(ISNUMBER(MATCH(D199, Mgt_Unit!$C$5:$C$1018, 0)), INDEX(Mgt_Unit!$B$5:$B$1018, MATCH(D199, Mgt_Unit!$C$5:$C$1018, 0)), "") -> jennifer.moore | D199: NAPESHM_MXSO01_106 | F199: SHI | J199: 8.35 | K199: 0.405
B200: =IF(ISNUMBER(MATCH(D200, Mgt_Unit!$C$5:$C$1018, 0)), INDEX(Mgt_Unit!$B$5:$B$1018, MATCH(D200, Mgt_Unit!$C$5:$C$1018, 0)), "") -> jennifer.moore | D200: NAPESHM_MXSO01_107 | F200: SHI | J200: 8.26 | K200: 0.502
B201: =IF(ISNUMBER(MATCH(D201, Mgt_Unit!$C$5:$C$1018, 0)), INDEX(Mgt_Unit!$B$5:$B$1018, MATCH(D201, Mgt_Unit!$C$5:$C$1018, 0)), "") -> jennifer.moore | D201: NAPESHM_MXSO01_108 | F201: SHI | J201: 8.18 | K201: 0.608
B202: =IF(ISNUMBER(MATCH(D202, Mgt_Unit!$C$5:$C$1018, 0)), INDEX(Mgt_Unit!$B$5:$B$1018, MATCH(D202, Mgt_Unit!$C$5:$C$1018, 0)), "") -> jennifer.moore | D202: NAPESHM_MXSO01_109 | F202: SHI | J202: 8.07 | K202: 0.662
B203: =IF(ISNUMBER(MATCH(D203, Mgt_Unit!$C$5:$C$1018, 0)), INDEX(Mgt_Unit!$B$5:$B$1018, MATCH(D203, Mgt_Unit!$C$5:$C$1018, 0)), "") -> jennifer.moore | D203: NAPESHM_MXSO01_110 | F203: SHI | J203: 8.27 | K203: 0.408
B204: =IF(ISNUMBER(MATCH(D204, Mgt_Unit!$C$5:$C$1018, 0)), INDEX(Mgt_Unit!$B$5:$B$1018, MATCH(D204, Mgt_Unit!$C$5:$C$1018, 0)), "") -> jennifer.moore | D204: NAPESHM_MXSO01_111 | F204: SHI | J204: 8.13 | K204: 1.017
B205: =IF(ISNUMBER(MATCH(D205, Mgt_Unit!$C$5:$C$1018, 0)), INDEX(Mgt_Unit!$B$5:$B$1018, MATCH(D205, Mgt_Unit!$C$5:$C$1018, 0)), "") -> jennifer.moore | D205: NAPESHM_MXSO01_100 | F205: SHI | J205: 7.98 | K205: 0.918
B206: =IF(ISNUMBER(MATCH(D206, Mgt_Unit!$C$5:$C$1018, 0)), INDEX(Mgt_Unit!$B$5:$B$1018, MATCH(D206, Mgt_Unit!$C$5:$C$1018, 0)), "") -> jennifer.moore | D206: NAPESHM_MXSO01_101 | F206: SHI | J206: 8.08 | K206: 0.927
B207: =IF(ISNUMBER(MATCH(D207, Mgt_Unit!$C$5:$C$1018, 0)), INDEX(Mgt_Unit!$B$5:$B$1018, MATCH(D207, Mgt_Unit!$C$5:$C$1018, 0)), "") -> jennifer.moore | D207: NAPESHM_MXSO01_102 | F207: SHI | J207: 8.1 | K207: 0.814
...

Sheet Dropdowns_Manual
A1: user_perm_list | B1: mgt_states_list | C1: mgt_study_list | D1: mgt_tile_drain_list | E1: mgt_tile_years_list | F1: crop_mix | G1: crop_cat_list | H1: crop_group_list | I1: crop_fallow_list | J1: crop_brassica_list | K1: crop_broadleaf_warm_list | L1: crop_broadleaf_cool_list | M1: crop_grass_warm_list | N1: crop_grass_cool_list | O1: crop_legume_warm_list | P1: crop_legume_cool_list | Q1: crop_horticulture_list | R1: crop_saline_list | S1: crop_all_crops_list | T1: Pasture_Mixed | U1: crop_yield_units_list | V1: crop_term_methods_list | W1: crop_res_mgt | X1: crop_irr_type_list | Y1: crop_irr_units | Z1: ops_phase_list | AA1: ops_equip_cat_list | AB1: ops_cultivator_list | AC1: ops_disk_list | AD1: ops_harrow_list | AE1: ops_plow_list | AF1: ops_roller_or_packer_list | AG1: ops_rotary_equip_list | AH1: ops_seedbed_prep_list | AI1: ops_soil_conditioner_list | AJ1: ops_miscellaneous_list | AK1: ops_equip_list | AL1: amend_cat_list | AM1: amend_fertilizer_list | AN1: amend_lime_list | AO1: amend_organic_list | AP1: amend_all_amend_list | AQ1: ani_type_list | AR1: ani_intensity_list
A2: admin | B2: Alabama | C2: Residue_M | D2: Yes | E2: None | F2: Yes | G2: Annual | H2: All_crops | I2: Fallow | J2: Broccoli | K2: Buckwheat | L2: Beets | M2: Bahiagrass | N2: Barley | O2: Beans, Cluster | P2: Alfalfa | Q2: Almond | R2: Alkaligrass | S2: Fallow | T2: Grasses, Cold | U2: lbs/acre | V2: Chemical | W2: baled | X2: Drip | Y2: inches | Z2: Pre-Plant | AA2: All_equip | AB2: Beet Cultivator | AC2: Bedder (Disk) | AD2: Finishing Harrow | AE2: Bedder (Disk) | AF2: Bed Roller | AG2: Rotary Hoe | AH2: Bed Roller | AI2: Coulter-Chisel | AJ2: Crust Buster | AK2: Bed Roller | AL2: All_amend | AM2: Fertilizer Blend | AN2: Agricultural Lime | AO2: Alfalfa Meal | AP2: Agricultural Lime | AQ2: Antelope, mature | AR2: None
A3: guest | B3: Alaska | C3: Residue_V | D3: No | E3: 0-5 | F3: No | G3: Perennial | H3: Brassica | J3: Camelina | K3: Chicory | L3: Camelina | M3: Bermuda | N3: Fescue, Fine | O3: Beans, Mung | P3: Beans, Bell | Q3: Apple | R3: Wheatgrass, Intermediate | S3: Alfalfa | T3: Grasses, Warm | U3: bushels/acre | V3: Mechanical | W3: incorporated | X3: Drip, Mobile | Y3: cm | Z3: Crop Mgt | AA3: Cultivator | AB3: Culti-Mulch Roller | AC3: Bedder Disk-Hipper | AD3: Flex-Tine Harrow | AE3: Bedder Shaper | AF3: Culti-Mulch Roller | AG3: Roterra | AH3: Bedder (Disk) | AI3: Crust Buster | AJ3: Cultiweeder | AK3: Bedder (Disk) | AL3: Fertilizer | AM3: Ammonium Nitrate | AN3: Burnt Lime/Quicklime | AO3: Beef Manure, solid | AP3: Burnt Lime/Quicklime | AQ3: Bison, mature | AR3: Light
B4: Arizona | C4: Tile_N | D4: Unsure | E4: 5-10 | G4: Cover | H4: Broadleaf_warm | J4: Canola | K4: Cotton | L4: Carrot | M4: Big Bluestem | N4: Fescue, Tall | O4: Cowpea | P4: Beans, Dry | Q4: Avocado | R4: Wheatgrass, RS Hybrid | S4: Alkaligrass | T4: Legumes, Cold | U4: kgs/acre | V4: Winter Kill | W4: not incorporated | X4: Furrow | Y4: mm | Z4: Termination | AA4: Disk | AB4: Cultiweeder | AC4: Disk-O-Vator (Discovator) | AD4: Harrow (Tines) | AE4: Chisel Plow | AF4: Culti-Packer Pulverizer | AG4: Roto-Tiller | AH4: Bedder Disk-Hipper | AI4: Culti-Packer Pulverizer | AJ4: Do-All | AK4: Bedder Disk-Hipper | AL4: Lime | AM4: Ammonium Nitrate Phosphate | AN4: Crushed | AO4: Beef Manure, slurry | AP4: Crushed | AQ4: Bull | AR4: Medium
B5: Arkansas | C5: Tile_S | E5: 11-20 | G5: Fallow | H5: Broadleaf_cool | J5: Collards | K5: Cucurbits | L5: Chard | M5: Corn | N5: Fescue, Tall (Forage) | O5: Fenugreek | P5: Beans, Fava | Q5: Cottonwoods | R5: Wheatgrass, Slender | S5: Almond | T5: Legumes, Warm | U5: lbs/hectare | V5: Annual Crop | X5: Sprinkler, Big Gun | Z5: Residue Mgt | AA5: Harrow | AB5: Duckfoot Cultivator | AC5: Disk Border Maker | AD5: Powered Spike Tooth Harrow | AE5: Disk Plow | AF5: Packer | AG5: Roto-Tiller | AH5: Bedder Disk-Row | AI5: Field Conditioner (Scratcher) | AJ5: Float | AK5: Bedder Disk-Row | AL5: Organic | AM5: Ammonium Phosphate Sulphate | AN5: Dolomitic | AO5: Biochar, Biosolids | AP5: Dolomitic | AQ5: Cattle, 1-yr-old | AR5: Heavy
B6: California | C6: Tillage | E6: >20 | G6: Cash | H6: Fallow | J6: Mustard | K6: Quinoa | L6: Flax | M6: Hay | N6: Fescue, Tall (Turf) | O6: Pea, Pigeon | P6: Beans, Pinto | Q6: Grapes | R6: Wheatgrass, Tall | S6: Apple | T6: Brassicas | U6: bushels/hectare | X6: Sprinkler, Linear | AA6: Plow | AB6: Field Cultivator | AC6: Disk Chisel (Mulch Tiller) | AD6: Roller Harrow | AE6: Furrow Diker | AF6: Packer Roller Flat Roller | AG6: Rotovator-Bedder | AH6: Bedder Shaper | AI6: Float | AJ6: Leveler | AK6: Bedder Shaper | AM6: Ammonium Polyphosphate | AN6: Hydrated Lime | AO6: Biochar, Manure | AP6: Hydrated Lime | AQ6: Cattle, 2-yr-old
B7: Colorado | C7: WV_Hops | E7: Unsure | H7: Grass_warm | J7: Mustard, Oriental | K7: Safflower | L7: Kale | M7: Haygrazer | N7: Oats | O7: Peanut | P7: Beans, Snap | Q7: Orange, Mandarin | R7: Wildrye, Russian | S7: Avocado | T7: Broadleaves, Cold | U7: kgs/hectare | X7: Sprinkler, Pivot | AA7: Roller_or_Packer | AB7: Furrow-Out Cultivator | AC7: Levee-Plow-Disc | AD7: Spike Tooth Harrow | AE7: Furrow-Out Cultivator | AF7: Rice Roller | AH7: Roller Groover | AI7: Hipper | AJ7: Paraplow | AK7: Beet Cultivator | AM7: Ammonium Sulphate | AN7: Other | AO7: Biochar, Herbaceous | AP7: Other | AQ7: Cow
B8: Connecticut | H8: Grass_cool | J8: Mustard, White | K8: Sugarcane | L8: Meadowfoam | M8: Millet | N8: Oats, Black | O8: Soybean | P8: Chickpea | Q8: Peach | S8: Barley | T8: Broadleaves, Warm | X8: None | AA8: Rotary_Equipment | AB8: Marker (Cultivator) | AC8: Offset Disk-Heavy Duty | AD8: Springtooth Harrow | AE8: Lister (Middle-Buster) | AF8: Roller Groover | AH8: Seedbed Roller | AI8: Land Plane-Leveler | AJ8: Rowbuck | AK8: Blade 10 Ft | AM8: Ammonium Thiosulphate | AN8: Pellitized Lime | AO8: Biochar, Rice | AP8: Pellitized Lime | AQ8: Cow/Calf
B9: Delaware | H9: Legume_warm | J9: Mustard, Yellow | K9: Sunflower | L9: Phacelia | M9: Millet, Foxtail | N9: Orchardgrass | O9: Soybean, Double-cropped | P9: Clover | Q9: Pear | S9: Beans, Bell | AA9: Seedbed_Preparation | AB9: Multi-Weeder | AC9: Offset Disk-Light Duty | AE9: Middle Buster | AF9: Roller Harrow | AI9: Landall | AJ9: Sand-Fighter | AK9: Chisel Plow | AM9: Calcium Ammonium Nitrate | AN9: Wet Lime | AO9: Biochar, Wood | AP9: Wet Lime | AQ9: Deer, Mule, mature
B10: Florida | H10: Legume_cool | J10: Radish | K10: Tomato | L10: Potato | M10: Millet, Hay | N10: Reed Canary Grass | O10: Soybean, Forage | P10: Clover, Balansa | Q10: Walnut | S10: Beans, Cluster | AA10: Soil_Conditioner | AB10: Rod Weeder | AC10: One-Way (Disk Tiller) | AE10: Moldboard Plow Reg | AF10: Seedbed Roller | AI10: Laser Planer | AJ10: Triple K | AK10: Coulter-Chisel | AM10: Calcium Nitrate | AO10: Blood, Dried | AP10: Fertilizer Blend | AQ10: Deer, White-tailed, mature
B11: Georgia | H11: Saline | J11: Rapeseed | K11: Okra | L11: Spinach | M11: Millet, Pearl | N11: Rye | O11: Sunnhemp | P11: Clover, Berseem | S11: Beans, Dry | AA11: Miscellaneous | AB11: Rolling Cultivator | AC11: Single Disk | AE11: One-Way (Disk Tiller) | AI11: Leveler | AK11: Crust Buster | AM11: Diammonium Phosphate | AO11: Bone Meal | AP11: Ammonium Nitrate | AQ11: Elk, mature
B12: Hawaii | H12: Horticulture | J12: Turnip | L12: Squash, Acorn | M12: Millet, Proso | N12: Rye, Cereal | P12: Clover, Crimson | S12: Beans, Fava | AB12: Row Conditioner | AC12: Tandem Disk Plow | AE12: Paraplow | AI12: Packer | AK12: Culti-Mulch Roller | AM12: Element-N | AO12: Chicken Broiler, solid | AP12: Ammonium Nitrate Phosphate | AQ12: Goat, mature
